<mujoco model="gripper_task">
    <compiler angle="radian" meshdir="./meshes_mujoco/" />
    <size njmax="3400" nconmax="800" />
    <asset>
        <mesh name="main body visual" file="main body visual.STL" />
        <mesh name="nut visual" file="nut visual.STL" />
        <mesh name="nut collision" file="nut collision.STL" />
        <mesh name="platform only visual" file="platform only visual.STL" />
        <mesh name="platform only collision" file="platform only collision.STL" />
        <mesh name="palm visual" file="palm visual.STL" />
        <mesh name="palm collision" file="palm collision.STL" />
    </asset>
    <worldbody>
        <body name="gripper_base_link" pos="0 0 0.386" quat="0 1 0 0">
            <inertial pos="0 0 0.025" quat="-0.00978477 0.713334 -0.700715 -0.00752147" mass="1.5" diaginertia="0.010083 0.00995 0.00512698" />
            <joint name="world_to_base" pos="0 0 0" axis="0 0 1" type="slide" limited="true" range="-1 1" damping="1" />
            <geom type="mesh" contype="0" conaffinity="0" group="1" mesh="main body visual" />
            <geom size="0.03 0.05" type="cylinder" />
            <body name="finger_1_intermediate" pos="0 0 0" quat="0.707107 0 -0.707107 0">
                <inertial pos="0 0 0" quat="0.37634 0.403447 0.585982 0.593484" mass="0.1" diaginertia="0.000166494 0.00015418 3.54554e-05" />
                <joint name="finger_1_prismatic_joint" pos="0 0 0" axis="0 1 0" type="slide" limited="true" range="0.049 0.134" damping="1" />
                <geom type="mesh" contype="0" conaffinity="0" group="1" mesh="nut visual" />
                <geom type="mesh" mesh="nut collision" />
                <body name="finger_1" pos="0 0 0">
                    <inertial pos="0 0 0" quat="0.37634 0.403447 0.585982 0.593484" mass="0.1" diaginertia="0.000166494 0.00015418 3.54554e-05" />
                    <joint name="finger_1_revolute_joint" pos="0 0 0" axis="0 0 1" limited="true" range="-0.7 0.7" damping="1" />
                    <geom type="mesh" contype="0" conaffinity="0" group="1" mesh="platform only visual" />
                    <geom type="mesh" mesh="platform only collision" />
                    <body name="finger_1_segment_link_1" pos="0.129 -0.007 0" quat="0.707107 0.707107 0 0">
                        <inertial pos="0 0 0" quat="0.5 0.5 -0.5 0.5" mass="0.00214808" diaginertia="1.84277e-07 1.40486e-07 4.40812e-08" />
                        <joint name="finger_1_segment_joint_0" pos="0 0 0" axis="0 1 0" limited="true" range="-1 1" damping="0.01" />
                        <geom size="0.00391667 0.014 0.00045" pos="0.00391667 0 0" type="box" contype="0" conaffinity="0" group="1" />
                        <geom size="0.00391667 0.014 0.00045" pos="0.00391667 0 0" type="box" />
                        <body name="finger_1_segment_link_2" pos="0.00783333 0 0">
                            <inertial pos="0 0 0" quat="0.5 0.5 -0.5 0.5" mass="0.00214808" diaginertia="1.84277e-07 1.40486e-07 4.40812e-08" />
                            <joint name="finger_1_segment_joint_1" pos="0 0 0" axis="0 1 0" limited="true" range="-1 1" damping="0.01" />
                            <geom size="0.00391667 0.014 0.00045" pos="0.00391667 0 0" type="box" contype="0" conaffinity="0" group="1" />
                            <geom size="0.00391667 0.014 0.00045" pos="0.00391667 0 0" type="box" />
                            <body name="finger_1_segment_link_3" pos="0.00783333 0 0">
                                <inertial pos="0 0 0" quat="0.5 0.5 -0.5 0.5" mass="0.00214808" diaginertia="1.84277e-07 1.40486e-07 4.40812e-08" />
                                <joint name="finger_1_segment_joint_2" pos="0 0 0" axis="0 1 0" limited="true" range="-1 1" damping="0.01" />
                                <geom size="0.00391667 0.014 0.00045" pos="0.00391667 0 0" type="box" contype="0" conaffinity="0" group="1" />
                                <geom size="0.00391667 0.014 0.00045" pos="0.00391667 0 0" type="box" />
                                <body name="finger_1_segment_link_4" pos="0.00783333 0 0">
                                    <inertial pos="0 0 0" quat="0.5 0.5 -0.5 0.5" mass="0.00214808" diaginertia="1.84277e-07 1.40486e-07 4.40812e-08" />
                                    <joint name="finger_1_segment_joint_3" pos="0 0 0" axis="0 1 0" limited="true" range="-1 1" damping="0.01" />
                                    <geom size="0.00391667 0.014 0.00045" pos="0.00391667 0 0" type="box" contype="0" conaffinity="0" group="1" />
                                    <geom size="0.00391667 0.014 0.00045" pos="0.00391667 0 0" type="box" />
                                    <body name="finger_1_segment_link_5" pos="0.00783333 0 0">
                                        <inertial pos="0 0 0" quat="0.5 0.5 -0.5 0.5" mass="0.00214808" diaginertia="1.84277e-07 1.40486e-07 4.40812e-08" />
                                        <joint name="finger_1_segment_joint_4" pos="0 0 0" axis="0 1 0" limited="true" range="-1 1" damping="0.01" />
                                        <geom size="0.00391667 0.014 0.00045" pos="0.00391667 0 0" type="box" contype="0" conaffinity="0" group="1" />
                                        <geom size="0.00391667 0.014 0.00045" pos="0.00391667 0 0" type="box" />
                                        <body name="finger_1_segment_link_6" pos="0.00783333 0 0">
                                            <inertial pos="0 0 0" quat="0.5 0.5 -0.5 0.5" mass="0.00214808" diaginertia="1.84277e-07 1.40486e-07 4.40812e-08" />
                                            <joint name="finger_1_segment_joint_5" pos="0 0 0" axis="0 1 0" limited="true" range="-1 1" damping="0.01" />
                                            <geom size="0.00391667 0.014 0.00045" pos="0.00391667 0 0" type="box" contype="0" conaffinity="0" group="1" />
                                            <geom size="0.00391667 0.014 0.00045" pos="0.00391667 0 0" type="box" />
                                            <body name="finger_1_segment_link_7" pos="0.00783333 0 0">
                                                <inertial pos="0 0 0" quat="0.5 0.5 -0.5 0.5" mass="0.00214808" diaginertia="1.84277e-07 1.40486e-07 4.40812e-08" />
                                                <joint name="finger_1_segment_joint_6" pos="0 0 0" axis="0 1 0" limited="true" range="-1 1" damping="0.01" />
                                                <geom size="0.00391667 0.014 0.00045" pos="0.00391667 0 0" type="box" contype="0" conaffinity="0" group="1" />
                                                <geom size="0.00391667 0.014 0.00045" pos="0.00391667 0 0" type="box" />
                                                <body name="finger_1_segment_link_8" pos="0.00783333 0 0">
                                                    <inertial pos="0 0 0" quat="0.5 0.5 -0.5 0.5" mass="0.00214808" diaginertia="1.84277e-07 1.40486e-07 4.40812e-08" />
                                                    <joint name="finger_1_segment_joint_7" pos="0 0 0" axis="0 1 0" limited="true" range="-1 1" damping="0.01" />
                                                    <geom size="0.00391667 0.014 0.00045" pos="0.00391667 0 0" type="box" contype="0" conaffinity="0" group="1" />
                                                    <geom size="0.00391667 0.014 0.00045" pos="0.00391667 0 0" type="box" />
                                                    <body name="finger_1_segment_link_9" pos="0.00783333 0 0">
                                                        <inertial pos="0 0 0" quat="0.5 0.5 -0.5 0.5" mass="0.00214808" diaginertia="1.84277e-07 1.40486e-07 4.40812e-08" />
                                                        <joint name="finger_1_segment_joint_8" pos="0 0 0" axis="0 1 0" limited="true" range="-1 1" damping="0.01" />
                                                        <geom size="0.00391667 0.014 0.00045" pos="0.00391667 0 0" type="box" contype="0" conaffinity="0" group="1" />
                                                        <geom size="0.00391667 0.014 0.00045" pos="0.00391667 0 0" type="box" />
                                                        <body name="finger_1_segment_link_10" pos="0.00783333 0 0">
                                                            <inertial pos="0 0 0" quat="0.5 0.5 -0.5 0.5" mass="0.00214808" diaginertia="1.84277e-07 1.40486e-07 4.40812e-08" />
                                                            <joint name="finger_1_segment_joint_9" pos="0 0 0" axis="0 1 0" limited="true" range="-1 1" damping="0.01" />
                                                            <geom size="0.00391667 0.014 0.00045" pos="0.00391667 0 0" type="box" contype="0" conaffinity="0" group="1" />
                                                            <geom size="0.00391667 0.014 0.00045" pos="0.00391667 0 0" type="box" />
                                                            <body name="finger_1_segment_link_11" pos="0.00783333 0 0">
                                                                <inertial pos="0 0 0" quat="0.5 0.5 -0.5 0.5" mass="0.00214808" diaginertia="1.84277e-07 1.40486e-07 4.40812e-08" />
                                                                <joint name="finger_1_segment_joint_10" pos="0 0 0" axis="0 1 0" limited="true" range="-1 1" damping="0.01" />
                                                                <geom size="0.00391667 0.014 0.00045" pos="0.00391667 0 0" type="box" contype="0" conaffinity="0" group="1" />
                                                                <geom size="0.00391667 0.014 0.00045" pos="0.00391667 0 0" type="box" />
                                                                <body name="finger_1_segment_link_12" pos="0.00783333 0 0">
                                                                    <inertial pos="0 0 0" quat="0.5 0.5 -0.5 0.5" mass="0.00214808" diaginertia="1.84277e-07 1.40486e-07 4.40812e-08" />
                                                                    <joint name="finger_1_segment_joint_11" pos="0 0 0" axis="0 1 0" limited="true" range="-1 1" damping="0.01" />
                                                                    <geom size="0.00391667 0.014 0.00045" pos="0.00391667 0 0" type="box" contype="0" conaffinity="0" group="1" />
                                                                    <geom size="0.00391667 0.014 0.00045" pos="0.00391667 0 0" type="box" />
                                                                    <body name="finger_1_segment_link_13" pos="0.00783333 0 0">
                                                                        <inertial pos="0 0 0" quat="0.5 0.5 -0.5 0.5" mass="0.00214808" diaginertia="1.84277e-07 1.40486e-07 4.40812e-08" />
                                                                        <joint name="finger_1_segment_joint_12" pos="0 0 0" axis="0 1 0" limited="true" range="-1 1" damping="0.01" />
                                                                        <geom size="0.00391667 0.014 0.00045" pos="0.00391667 0 0" type="box" contype="0" conaffinity="0" group="1" />
                                                                        <geom size="0.00391667 0.014 0.00045" pos="0.00391667 0 0" type="box" />
                                                                        <body name="finger_1_segment_link_14" pos="0.00783333 0 0">
                                                                            <inertial pos="0 0 0" quat="0.5 0.5 -0.5 0.5" mass="0.00214808" diaginertia="1.84277e-07 1.40486e-07 4.40812e-08" />
                                                                            <joint name="finger_1_segment_joint_13" pos="0 0 0" axis="0 1 0" limited="true" range="-1 1" damping="0.01" />
                                                                            <geom size="0.00391667 0.014 0.00045" pos="0.00391667 0 0" type="box" contype="0" conaffinity="0" group="1" />
                                                                            <geom size="0.00391667 0.014 0.00045" pos="0.00391667 0 0" type="box" />
                                                                            <body name="finger_1_segment_link_15" pos="0.00783333 0 0">
                                                                                <inertial pos="0 0 0" quat="0.5 0.5 -0.5 0.5" mass="0.00214808" diaginertia="1.84277e-07 1.40486e-07 4.40812e-08" />
                                                                                <joint name="finger_1_segment_joint_14" pos="0 0 0" axis="0 1 0" limited="true" range="-1 1" damping="0.01" />
                                                                                <geom size="0.00391667 0.014 0.00045" pos="0.00391667 0 0" type="box" contype="0" conaffinity="0" group="1" />
                                                                                <geom size="0.00391667 0.014 0.00045" pos="0.00391667 0 0" type="box" />
                                                                                <body name="finger_1_segment_link_16" pos="0.00783333 0 0">
                                                                                    <inertial pos="0 0 0" quat="0.5 0.5 -0.5 0.5" mass="0.00214808" diaginertia="1.84277e-07 1.40486e-07 4.40812e-08" />
                                                                                    <joint name="finger_1_segment_joint_15" pos="0 0 0" axis="0 1 0" limited="true" range="-1 1" damping="0.01" />
                                                                                    <geom size="0.00391667 0.014 0.00045" pos="0.00391667 0 0" type="box" contype="0" conaffinity="0" group="1" />
                                                                                    <geom size="0.00391667 0.014 0.00045" pos="0.00391667 0 0" type="box" />
                                                                                    <body name="finger_1_segment_link_17" pos="0.00783333 0 0">
                                                                                        <inertial pos="0 0 0" quat="0.5 0.5 -0.5 0.5" mass="0.00214808" diaginertia="1.84277e-07 1.40486e-07 4.40812e-08" />
                                                                                        <joint name="finger_1_segment_joint_16" pos="0 0 0" axis="0 1 0" limited="true" range="-1 1" damping="0.01" />
                                                                                        <geom size="0.00391667 0.014 0.00045" pos="0.00391667 0 0" type="box" contype="0" conaffinity="0" group="1" />
                                                                                        <geom size="0.00391667 0.014 0.00045" pos="0.00391667 0 0" type="box" />
                                                                                        <body name="finger_1_segment_link_18" pos="0.00783333 0 0">
                                                                                            <inertial pos="0 0 0" quat="0.5 0.5 -0.5 0.5" mass="0.00214808" diaginertia="1.84277e-07 1.40486e-07 4.40812e-08" />
                                                                                            <joint name="finger_1_segment_joint_17" pos="0 0 0" axis="0 1 0" limited="true" range="-1 1" damping="0.01" />
                                                                                            <geom size="0.00391667 0.014 0.00045" pos="0.00391667 0 0" type="box" contype="0" conaffinity="0" group="1" />
                                                                                            <geom size="0.00391667 0.014 0.00045" pos="0.00391667 0 0" type="box" />
                                                                                            <body name="finger_1_segment_link_19" pos="0.00783333 0 0">
                                                                                                <inertial pos="0 0 0" quat="0.5 0.5 -0.5 0.5" mass="0.00214808" diaginertia="1.84277e-07 1.40486e-07 4.40812e-08" />
                                                                                                <joint name="finger_1_segment_joint_18" pos="0 0 0" axis="0 1 0" limited="true" range="-1 1" damping="0.01" />
                                                                                                <geom size="0.00391667 0.014 0.00045" pos="0.00391667 0 0" type="box" contype="0" conaffinity="0" group="1" />
                                                                                                <geom size="0.00391667 0.014 0.00045" pos="0.00391667 0 0" type="box" />
                                                                                                <body name="finger_1_segment_link_20" pos="0.00783333 0 0">
                                                                                                    <inertial pos="0 0 0" quat="0.5 0.5 -0.5 0.5" mass="0.00214808" diaginertia="1.84277e-07 1.40486e-07 4.40812e-08" />
                                                                                                    <joint name="finger_1_segment_joint_19" pos="0 0 0" axis="0 1 0" limited="true" range="-1 1" damping="0.01" />
                                                                                                    <geom size="0.00391667 0.014 0.00045" pos="0.00391667 0 0" type="box" contype="0" conaffinity="0" group="1" />
                                                                                                    <geom size="0.00391667 0.014 0.00045" pos="0.00391667 0 0" type="box" />
                                                                                                    <body name="finger_1_segment_link_21" pos="0.00783333 0 0">
                                                                                                        <inertial pos="0 0 0" quat="0.5 0.5 -0.5 0.5" mass="0.00214808" diaginertia="1.84277e-07 1.40486e-07 4.40812e-08" />
                                                                                                        <joint name="finger_1_segment_joint_20" pos="0 0 0" axis="0 1 0" limited="true" range="-1 1" damping="0.01" />
                                                                                                        <geom size="0.00391667 0.014 0.00045" pos="0.00391667 0 0" type="box" contype="0" conaffinity="0" group="1" />
                                                                                                        <geom size="0.00391667 0.014 0.00045" pos="0.00391667 0 0" type="box" />
                                                                                                        <body name="finger_1_segment_link_22" pos="0.00783333 0 0">
                                                                                                            <inertial pos="0 0 0" quat="0.5 0.5 -0.5 0.5" mass="0.00214808" diaginertia="1.84277e-07 1.40486e-07 4.40812e-08" />
                                                                                                            <joint name="finger_1_segment_joint_21" pos="0 0 0" axis="0 1 0" limited="true" range="-1 1" damping="0.01" />
                                                                                                            <geom size="0.00391667 0.014 0.00045" pos="0.00391667 0 0" type="box" contype="0" conaffinity="0" group="1" />
                                                                                                            <geom size="0.00391667 0.014 0.00045" pos="0.00391667 0 0" type="box" />
                                                                                                            <body name="finger_1_segment_link_23" pos="0.00783333 0 0">
                                                                                                                <inertial pos="0 0 0" quat="0.5 0.5 -0.5 0.5" mass="0.00214808" diaginertia="1.84277e-07 1.40486e-07 4.40812e-08" />
                                                                                                                <joint name="finger_1_segment_joint_22" pos="0 0 0" axis="0 1 0" limited="true" range="-1 1" damping="0.01" />
                                                                                                                <geom size="0.00391667 0.014 0.00045" pos="0.00391667 0 0" type="box" contype="0" conaffinity="0" group="1" />
                                                                                                                <geom size="0.00391667 0.014 0.00045" pos="0.00391667 0 0" type="box" />
                                                                                                                <body name="finger_1_segment_link_24" pos="0.00783333 0 0">
                                                                                                                    <inertial pos="0 0 0" quat="0.5 0.5 -0.5 0.5" mass="0.00214808" diaginertia="1.84277e-07 1.40486e-07 4.40812e-08" />
                                                                                                                    <joint name="finger_1_segment_joint_23" pos="0 0 0" axis="0 1 0" limited="true" range="-1 1" damping="0.01" />
                                                                                                                    <geom size="0.00391667 0.014 0.00045" pos="0.00391667 0 0" type="box" contype="0" conaffinity="0" group="1" />
                                                                                                                    <geom size="0.00391667 0.014 0.00045" pos="0.00391667 0 0" type="box" />
                                                                                                                    <body name="finger_1_segment_link_25" pos="0.00783333 0 0">
                                                                                                                        <inertial pos="0 0 0" quat="0.5 0.5 -0.5 0.5" mass="0.00214808" diaginertia="1.84277e-07 1.40486e-07 4.40812e-08" />
                                                                                                                        <joint name="finger_1_segment_joint_24" pos="0 0 0" axis="0 1 0" limited="true" range="-1 1" damping="0.01" />
                                                                                                                        <geom size="0.00391667 0.014 0.00045" pos="0.00391667 0 0" type="box" contype="0" conaffinity="0" group="1" />
                                                                                                                        <geom size="0.00391667 0.014 0.00045" pos="0.00391667 0 0" type="box" />
                                                                                                                        <body name="finger_1_segment_link_26" pos="0.00783333 0 0">
                                                                                                                            <inertial pos="0 0 0" quat="0.5 0.5 -0.5 0.5" mass="0.00214808" diaginertia="1.84277e-07 1.40486e-07 4.40812e-08" />
                                                                                                                            <joint name="finger_1_segment_joint_25" pos="0 0 0" axis="0 1 0" limited="true" range="-1 1" damping="0.01" />
                                                                                                                            <geom size="0.00391667 0.014 0.00045" pos="0.00391667 0 0" type="box" contype="0" conaffinity="0" group="1" />
                                                                                                                            <geom size="0.00391667 0.014 0.00045" pos="0.00391667 0 0" type="box" />
                                                                                                                            <body name="finger_1_segment_link_27" pos="0.00783333 0 0">
                                                                                                                                <inertial pos="0 0 0" quat="0.5 0.5 -0.5 0.5" mass="0.00214808" diaginertia="1.84277e-07 1.40486e-07 4.40812e-08" />
                                                                                                                                <joint name="finger_1_segment_joint_26" pos="0 0 0" axis="0 1 0" limited="true" range="-1 1" damping="0.01" />
                                                                                                                                <geom size="0.00391667 0.014 0.00045" pos="0.00391667 0 0" type="box" contype="0" conaffinity="0" group="1" />
                                                                                                                                <geom size="0.00391667 0.014 0.00045" pos="0.00391667 0 0" type="box" />
                                                                                                                                <body name="finger_1_segment_link_28" pos="0.00783333 0 0">
                                                                                                                                    <inertial pos="0 0 0" quat="0.5 0.5 -0.5 0.5" mass="0.00214808" diaginertia="1.84277e-07 1.40486e-07 4.40812e-08" />
                                                                                                                                    <joint name="finger_1_segment_joint_27" pos="0 0 0" axis="0 1 0" limited="true" range="-1 1" damping="0.01" />
                                                                                                                                    <geom size="0.00391667 0.014 0.00045" pos="0.00391667 0 0" type="box" contype="0" conaffinity="0" group="1" />
                                                                                                                                    <geom size="0.00391667 0.014 0.00045" pos="0.00391667 0 0" type="box" />
                                                                                                                                    <body name="finger_1_segment_link_29" pos="0.00783333 0 0">
                                                                                                                                        <inertial pos="0 0 0" quat="0.5 0.5 -0.5 0.5" mass="0.00214808" diaginertia="1.84277e-07 1.40486e-07 4.40812e-08" />
                                                                                                                                        <joint name="finger_1_segment_joint_28" pos="0 0 0" axis="0 1 0" limited="true" range="-1 1" damping="0.01" />
                                                                                                                                        <geom size="0.00391667 0.014 0.00045" pos="0.00391667 0 0" type="box" contype="0" conaffinity="0" group="1" />
                                                                                                                                        <geom size="0.00391667 0.014 0.00045" pos="0.00391667 0 0" type="box" />
                                                                                                                                        <body name="finger_1_segment_link_30" pos="0.00783333 0 0">
                                                                                                                                            <inertial pos="0.00391667 0 0" quat="0.5 0.5 -0.5 0.5" mass="0.00429616" diaginertia="3.90668e-07 3.24764e-07 1.54067e-07" />
                                                                                                                                            <joint name="finger_1_segment_joint_29" pos="0 0 0" axis="0 1 0" limited="true" range="-1 1" damping="0.01" />
                                                                                                                                            <geom size="0.00391667 0.014 0.00045" pos="0.00391667 0 0" type="box" contype="0" conaffinity="0" group="1" />
                                                                                                                                            <geom size="0.00391667 0.014 0.00045" pos="0.00391667 0 0" type="box" />
                                                                                                                                            <geom size="0.01925 0.014 0.00045" pos="0.00783333 0 0.01925" quat="0.707107 0 -0.707107 0" type="box" contype="0" conaffinity="0" group="1" />
                                                                                                                                            <geom size="0.01925 0.014 0.00045" pos="0.00783333 0 0.01925" quat="0.707107 0 -0.707107 0" type="box" />
                                                                                                                                        </body>
                                                                                                                                    </body>
                                                                                                                                </body>
                                                                                                                            </body>
                                                                                                                        </body>
                                                                                                                    </body>
                                                                                                                </body>
                                                                                                            </body>
                                                                                                        </body>
                                                                                                    </body>
                                                                                                </body>
                                                                                            </body>
                                                                                        </body>
                                                                                    </body>
                                                                                </body>
                                                                            </body>
                                                                        </body>
                                                                    </body>
                                                                </body>
                                                            </body>
                                                        </body>
                                                    </body>
                                                </body>
                                            </body>
                                        </body>
                                    </body>
                                </body>
                            </body>
                        </body>
                    </body>
                </body>
            </body>
            <body name="finger_2_intermediate" pos="0 0 0" quat="0.353553 -0.612372 -0.353553 -0.612372">
                <inertial pos="0 0 0" quat="0.37634 0.403447 0.585982 0.593484" mass="0.1" diaginertia="0.000166494 0.00015418 3.54554e-05" />
                <joint name="finger_2_prismatic_joint" pos="0 0 0" axis="0 1 0" type="slide" limited="true" range="0.049 0.134" damping="1" />
                <geom type="mesh" contype="0" conaffinity="0" group="1" mesh="nut visual" />
                <geom type="mesh" mesh="nut collision" />
                <body name="finger_2" pos="0 0 0">
                    <inertial pos="0 0 0" quat="0.37634 0.403447 0.585982 0.593484" mass="0.1" diaginertia="0.000166494 0.00015418 3.54554e-05" />
                    <joint name="finger_2_revolute_joint" pos="0 0 0" axis="0 0 1" limited="true" range="-0.7 0.7" damping="1" />
                    <geom type="mesh" contype="0" conaffinity="0" group="1" mesh="platform only visual" />
                    <geom type="mesh" mesh="platform only collision" />
                    <body name="finger_2_segment_link_1" pos="0.129 -0.007 0" quat="0.707107 0.707107 0 0">
                        <inertial pos="0 0 0" quat="0.5 0.5 -0.5 0.5" mass="0.00214808" diaginertia="1.84277e-07 1.40486e-07 4.40812e-08" />
                        <joint name="finger_2_segment_joint_0" pos="0 0 0" axis="0 1 0" limited="true" range="-1 1" damping="0.01" />
                        <geom size="0.00391667 0.014 0.00045" pos="0.00391667 0 0" type="box" contype="0" conaffinity="0" group="1" />
                        <geom size="0.00391667 0.014 0.00045" pos="0.00391667 0 0" type="box" />
                        <body name="finger_2_segment_link_2" pos="0.00783333 0 0">
                            <inertial pos="0 0 0" quat="0.5 0.5 -0.5 0.5" mass="0.00214808" diaginertia="1.84277e-07 1.40486e-07 4.40812e-08" />
                            <joint name="finger_2_segment_joint_1" pos="0 0 0" axis="0 1 0" limited="true" range="-1 1" damping="0.01" />
                            <geom size="0.00391667 0.014 0.00045" pos="0.00391667 0 0" type="box" contype="0" conaffinity="0" group="1" />
                            <geom size="0.00391667 0.014 0.00045" pos="0.00391667 0 0" type="box" />
                            <body name="finger_2_segment_link_3" pos="0.00783333 0 0">
                                <inertial pos="0 0 0" quat="0.5 0.5 -0.5 0.5" mass="0.00214808" diaginertia="1.84277e-07 1.40486e-07 4.40812e-08" />
                                <joint name="finger_2_segment_joint_2" pos="0 0 0" axis="0 1 0" limited="true" range="-1 1" damping="0.01" />
                                <geom size="0.00391667 0.014 0.00045" pos="0.00391667 0 0" type="box" contype="0" conaffinity="0" group="1" />
                                <geom size="0.00391667 0.014 0.00045" pos="0.00391667 0 0" type="box" />
                                <body name="finger_2_segment_link_4" pos="0.00783333 0 0">
                                    <inertial pos="0 0 0" quat="0.5 0.5 -0.5 0.5" mass="0.00214808" diaginertia="1.84277e-07 1.40486e-07 4.40812e-08" />
                                    <joint name="finger_2_segment_joint_3" pos="0 0 0" axis="0 1 0" limited="true" range="-1 1" damping="0.01" />
                                    <geom size="0.00391667 0.014 0.00045" pos="0.00391667 0 0" type="box" contype="0" conaffinity="0" group="1" />
                                    <geom size="0.00391667 0.014 0.00045" pos="0.00391667 0 0" type="box" />
                                    <body name="finger_2_segment_link_5" pos="0.00783333 0 0">
                                        <inertial pos="0 0 0" quat="0.5 0.5 -0.5 0.5" mass="0.00214808" diaginertia="1.84277e-07 1.40486e-07 4.40812e-08" />
                                        <joint name="finger_2_segment_joint_4" pos="0 0 0" axis="0 1 0" limited="true" range="-1 1" damping="0.01" />
                                        <geom size="0.00391667 0.014 0.00045" pos="0.00391667 0 0" type="box" contype="0" conaffinity="0" group="1" />
                                        <geom size="0.00391667 0.014 0.00045" pos="0.00391667 0 0" type="box" />
                                        <body name="finger_2_segment_link_6" pos="0.00783333 0 0">
                                            <inertial pos="0 0 0" quat="0.5 0.5 -0.5 0.5" mass="0.00214808" diaginertia="1.84277e-07 1.40486e-07 4.40812e-08" />
                                            <joint name="finger_2_segment_joint_5" pos="0 0 0" axis="0 1 0" limited="true" range="-1 1" damping="0.01" />
                                            <geom size="0.00391667 0.014 0.00045" pos="0.00391667 0 0" type="box" contype="0" conaffinity="0" group="1" />
                                            <geom size="0.00391667 0.014 0.00045" pos="0.00391667 0 0" type="box" />
                                            <body name="finger_2_segment_link_7" pos="0.00783333 0 0">
                                                <inertial pos="0 0 0" quat="0.5 0.5 -0.5 0.5" mass="0.00214808" diaginertia="1.84277e-07 1.40486e-07 4.40812e-08" />
                                                <joint name="finger_2_segment_joint_6" pos="0 0 0" axis="0 1 0" limited="true" range="-1 1" damping="0.01" />
                                                <geom size="0.00391667 0.014 0.00045" pos="0.00391667 0 0" type="box" contype="0" conaffinity="0" group="1" />
                                                <geom size="0.00391667 0.014 0.00045" pos="0.00391667 0 0" type="box" />
                                                <body name="finger_2_segment_link_8" pos="0.00783333 0 0">
                                                    <inertial pos="0 0 0" quat="0.5 0.5 -0.5 0.5" mass="0.00214808" diaginertia="1.84277e-07 1.40486e-07 4.40812e-08" />
                                                    <joint name="finger_2_segment_joint_7" pos="0 0 0" axis="0 1 0" limited="true" range="-1 1" damping="0.01" />
                                                    <geom size="0.00391667 0.014 0.00045" pos="0.00391667 0 0" type="box" contype="0" conaffinity="0" group="1" />
                                                    <geom size="0.00391667 0.014 0.00045" pos="0.00391667 0 0" type="box" />
                                                    <body name="finger_2_segment_link_9" pos="0.00783333 0 0">
                                                        <inertial pos="0 0 0" quat="0.5 0.5 -0.5 0.5" mass="0.00214808" diaginertia="1.84277e-07 1.40486e-07 4.40812e-08" />
                                                        <joint name="finger_2_segment_joint_8" pos="0 0 0" axis="0 1 0" limited="true" range="-1 1" damping="0.01" />
                                                        <geom size="0.00391667 0.014 0.00045" pos="0.00391667 0 0" type="box" contype="0" conaffinity="0" group="1" />
                                                        <geom size="0.00391667 0.014 0.00045" pos="0.00391667 0 0" type="box" />
                                                        <body name="finger_2_segment_link_10" pos="0.00783333 0 0">
                                                            <inertial pos="0 0 0" quat="0.5 0.5 -0.5 0.5" mass="0.00214808" diaginertia="1.84277e-07 1.40486e-07 4.40812e-08" />
                                                            <joint name="finger_2_segment_joint_9" pos="0 0 0" axis="0 1 0" limited="true" range="-1 1" damping="0.01" />
                                                            <geom size="0.00391667 0.014 0.00045" pos="0.00391667 0 0" type="box" contype="0" conaffinity="0" group="1" />
                                                            <geom size="0.00391667 0.014 0.00045" pos="0.00391667 0 0" type="box" />
                                                            <body name="finger_2_segment_link_11" pos="0.00783333 0 0">
                                                                <inertial pos="0 0 0" quat="0.5 0.5 -0.5 0.5" mass="0.00214808" diaginertia="1.84277e-07 1.40486e-07 4.40812e-08" />
                                                                <joint name="finger_2_segment_joint_10" pos="0 0 0" axis="0 1 0" limited="true" range="-1 1" damping="0.01" />
                                                                <geom size="0.00391667 0.014 0.00045" pos="0.00391667 0 0" type="box" contype="0" conaffinity="0" group="1" />
                                                                <geom size="0.00391667 0.014 0.00045" pos="0.00391667 0 0" type="box" />
                                                                <body name="finger_2_segment_link_12" pos="0.00783333 0 0">
                                                                    <inertial pos="0 0 0" quat="0.5 0.5 -0.5 0.5" mass="0.00214808" diaginertia="1.84277e-07 1.40486e-07 4.40812e-08" />
                                                                    <joint name="finger_2_segment_joint_11" pos="0 0 0" axis="0 1 0" limited="true" range="-1 1" damping="0.01" />
                                                                    <geom size="0.00391667 0.014 0.00045" pos="0.00391667 0 0" type="box" contype="0" conaffinity="0" group="1" />
                                                                    <geom size="0.00391667 0.014 0.00045" pos="0.00391667 0 0" type="box" />
                                                                    <body name="finger_2_segment_link_13" pos="0.00783333 0 0">
                                                                        <inertial pos="0 0 0" quat="0.5 0.5 -0.5 0.5" mass="0.00214808" diaginertia="1.84277e-07 1.40486e-07 4.40812e-08" />
                                                                        <joint name="finger_2_segment_joint_12" pos="0 0 0" axis="0 1 0" limited="true" range="-1 1" damping="0.01" />
                                                                        <geom size="0.00391667 0.014 0.00045" pos="0.00391667 0 0" type="box" contype="0" conaffinity="0" group="1" />
                                                                        <geom size="0.00391667 0.014 0.00045" pos="0.00391667 0 0" type="box" />
                                                                        <body name="finger_2_segment_link_14" pos="0.00783333 0 0">
                                                                            <inertial pos="0 0 0" quat="0.5 0.5 -0.5 0.5" mass="0.00214808" diaginertia="1.84277e-07 1.40486e-07 4.40812e-08" />
                                                                            <joint name="finger_2_segment_joint_13" pos="0 0 0" axis="0 1 0" limited="true" range="-1 1" damping="0.01" />
                                                                            <geom size="0.00391667 0.014 0.00045" pos="0.00391667 0 0" type="box" contype="0" conaffinity="0" group="1" />
                                                                            <geom size="0.00391667 0.014 0.00045" pos="0.00391667 0 0" type="box" />
                                                                            <body name="finger_2_segment_link_15" pos="0.00783333 0 0">
                                                                                <inertial pos="0 0 0" quat="0.5 0.5 -0.5 0.5" mass="0.00214808" diaginertia="1.84277e-07 1.40486e-07 4.40812e-08" />
                                                                                <joint name="finger_2_segment_joint_14" pos="0 0 0" axis="0 1 0" limited="true" range="-1 1" damping="0.01" />
                                                                                <geom size="0.00391667 0.014 0.00045" pos="0.00391667 0 0" type="box" contype="0" conaffinity="0" group="1" />
                                                                                <geom size="0.00391667 0.014 0.00045" pos="0.00391667 0 0" type="box" />
                                                                                <body name="finger_2_segment_link_16" pos="0.00783333 0 0">
                                                                                    <inertial pos="0 0 0" quat="0.5 0.5 -0.5 0.5" mass="0.00214808" diaginertia="1.84277e-07 1.40486e-07 4.40812e-08" />
                                                                                    <joint name="finger_2_segment_joint_15" pos="0 0 0" axis="0 1 0" limited="true" range="-1 1" damping="0.01" />
                                                                                    <geom size="0.00391667 0.014 0.00045" pos="0.00391667 0 0" type="box" contype="0" conaffinity="0" group="1" />
                                                                                    <geom size="0.00391667 0.014 0.00045" pos="0.00391667 0 0" type="box" />
                                                                                    <body name="finger_2_segment_link_17" pos="0.00783333 0 0">
                                                                                        <inertial pos="0 0 0" quat="0.5 0.5 -0.5 0.5" mass="0.00214808" diaginertia="1.84277e-07 1.40486e-07 4.40812e-08" />
                                                                                        <joint name="finger_2_segment_joint_16" pos="0 0 0" axis="0 1 0" limited="true" range="-1 1" damping="0.01" />
                                                                                        <geom size="0.00391667 0.014 0.00045" pos="0.00391667 0 0" type="box" contype="0" conaffinity="0" group="1" />
                                                                                        <geom size="0.00391667 0.014 0.00045" pos="0.00391667 0 0" type="box" />
                                                                                        <body name="finger_2_segment_link_18" pos="0.00783333 0 0">
                                                                                            <inertial pos="0 0 0" quat="0.5 0.5 -0.5 0.5" mass="0.00214808" diaginertia="1.84277e-07 1.40486e-07 4.40812e-08" />
                                                                                            <joint name="finger_2_segment_joint_17" pos="0 0 0" axis="0 1 0" limited="true" range="-1 1" damping="0.01" />
                                                                                            <geom size="0.00391667 0.014 0.00045" pos="0.00391667 0 0" type="box" contype="0" conaffinity="0" group="1" />
                                                                                            <geom size="0.00391667 0.014 0.00045" pos="0.00391667 0 0" type="box" />
                                                                                            <body name="finger_2_segment_link_19" pos="0.00783333 0 0">
                                                                                                <inertial pos="0 0 0" quat="0.5 0.5 -0.5 0.5" mass="0.00214808" diaginertia="1.84277e-07 1.40486e-07 4.40812e-08" />
                                                                                                <joint name="finger_2_segment_joint_18" pos="0 0 0" axis="0 1 0" limited="true" range="-1 1" damping="0.01" />
                                                                                                <geom size="0.00391667 0.014 0.00045" pos="0.00391667 0 0" type="box" contype="0" conaffinity="0" group="1" />
                                                                                                <geom size="0.00391667 0.014 0.00045" pos="0.00391667 0 0" type="box" />
                                                                                                <body name="finger_2_segment_link_20" pos="0.00783333 0 0">
                                                                                                    <inertial pos="0 0 0" quat="0.5 0.5 -0.5 0.5" mass="0.00214808" diaginertia="1.84277e-07 1.40486e-07 4.40812e-08" />
                                                                                                    <joint name="finger_2_segment_joint_19" pos="0 0 0" axis="0 1 0" limited="true" range="-1 1" damping="0.01" />
                                                                                                    <geom size="0.00391667 0.014 0.00045" pos="0.00391667 0 0" type="box" contype="0" conaffinity="0" group="1" />
                                                                                                    <geom size="0.00391667 0.014 0.00045" pos="0.00391667 0 0" type="box" />
                                                                                                    <body name="finger_2_segment_link_21" pos="0.00783333 0 0">
                                                                                                        <inertial pos="0 0 0" quat="0.5 0.5 -0.5 0.5" mass="0.00214808" diaginertia="1.84277e-07 1.40486e-07 4.40812e-08" />
                                                                                                        <joint name="finger_2_segment_joint_20" pos="0 0 0" axis="0 1 0" limited="true" range="-1 1" damping="0.01" />
                                                                                                        <geom size="0.00391667 0.014 0.00045" pos="0.00391667 0 0" type="box" contype="0" conaffinity="0" group="1" />
                                                                                                        <geom size="0.00391667 0.014 0.00045" pos="0.00391667 0 0" type="box" />
                                                                                                        <body name="finger_2_segment_link_22" pos="0.00783333 0 0">
                                                                                                            <inertial pos="0 0 0" quat="0.5 0.5 -0.5 0.5" mass="0.00214808" diaginertia="1.84277e-07 1.40486e-07 4.40812e-08" />
                                                                                                            <joint name="finger_2_segment_joint_21" pos="0 0 0" axis="0 1 0" limited="true" range="-1 1" damping="0.01" />
                                                                                                            <geom size="0.00391667 0.014 0.00045" pos="0.00391667 0 0" type="box" contype="0" conaffinity="0" group="1" />
                                                                                                            <geom size="0.00391667 0.014 0.00045" pos="0.00391667 0 0" type="box" />
                                                                                                            <body name="finger_2_segment_link_23" pos="0.00783333 0 0">
                                                                                                                <inertial pos="0 0 0" quat="0.5 0.5 -0.5 0.5" mass="0.00214808" diaginertia="1.84277e-07 1.40486e-07 4.40812e-08" />
                                                                                                                <joint name="finger_2_segment_joint_22" pos="0 0 0" axis="0 1 0" limited="true" range="-1 1" damping="0.01" />
                                                                                                                <geom size="0.00391667 0.014 0.00045" pos="0.00391667 0 0" type="box" contype="0" conaffinity="0" group="1" />
                                                                                                                <geom size="0.00391667 0.014 0.00045" pos="0.00391667 0 0" type="box" />
                                                                                                                <body name="finger_2_segment_link_24" pos="0.00783333 0 0">
                                                                                                                    <inertial pos="0 0 0" quat="0.5 0.5 -0.5 0.5" mass="0.00214808" diaginertia="1.84277e-07 1.40486e-07 4.40812e-08" />
                                                                                                                    <joint name="finger_2_segment_joint_23" pos="0 0 0" axis="0 1 0" limited="true" range="-1 1" damping="0.01" />
                                                                                                                    <geom size="0.00391667 0.014 0.00045" pos="0.00391667 0 0" type="box" contype="0" conaffinity="0" group="1" />
                                                                                                                    <geom size="0.00391667 0.014 0.00045" pos="0.00391667 0 0" type="box" />
                                                                                                                    <body name="finger_2_segment_link_25" pos="0.00783333 0 0">
                                                                                                                        <inertial pos="0 0 0" quat="0.5 0.5 -0.5 0.5" mass="0.00214808" diaginertia="1.84277e-07 1.40486e-07 4.40812e-08" />
                                                                                                                        <joint name="finger_2_segment_joint_24" pos="0 0 0" axis="0 1 0" limited="true" range="-1 1" damping="0.01" />
                                                                                                                        <geom size="0.00391667 0.014 0.00045" pos="0.00391667 0 0" type="box" contype="0" conaffinity="0" group="1" />
                                                                                                                        <geom size="0.00391667 0.014 0.00045" pos="0.00391667 0 0" type="box" />
                                                                                                                        <body name="finger_2_segment_link_26" pos="0.00783333 0 0">
                                                                                                                            <inertial pos="0 0 0" quat="0.5 0.5 -0.5 0.5" mass="0.00214808" diaginertia="1.84277e-07 1.40486e-07 4.40812e-08" />
                                                                                                                            <joint name="finger_2_segment_joint_25" pos="0 0 0" axis="0 1 0" limited="true" range="-1 1" damping="0.01" />
                                                                                                                            <geom size="0.00391667 0.014 0.00045" pos="0.00391667 0 0" type="box" contype="0" conaffinity="0" group="1" />
                                                                                                                            <geom size="0.00391667 0.014 0.00045" pos="0.00391667 0 0" type="box" />
                                                                                                                            <body name="finger_2_segment_link_27" pos="0.00783333 0 0">
                                                                                                                                <inertial pos="0 0 0" quat="0.5 0.5 -0.5 0.5" mass="0.00214808" diaginertia="1.84277e-07 1.40486e-07 4.40812e-08" />
                                                                                                                                <joint name="finger_2_segment_joint_26" pos="0 0 0" axis="0 1 0" limited="true" range="-1 1" damping="0.01" />
                                                                                                                                <geom size="0.00391667 0.014 0.00045" pos="0.00391667 0 0" type="box" contype="0" conaffinity="0" group="1" />
                                                                                                                                <geom size="0.00391667 0.014 0.00045" pos="0.00391667 0 0" type="box" />
                                                                                                                                <body name="finger_2_segment_link_28" pos="0.00783333 0 0">
                                                                                                                                    <inertial pos="0 0 0" quat="0.5 0.5 -0.5 0.5" mass="0.00214808" diaginertia="1.84277e-07 1.40486e-07 4.40812e-08" />
                                                                                                                                    <joint name="finger_2_segment_joint_27" pos="0 0 0" axis="0 1 0" limited="true" range="-1 1" damping="0.01" />
                                                                                                                                    <geom size="0.00391667 0.014 0.00045" pos="0.00391667 0 0" type="box" contype="0" conaffinity="0" group="1" />
                                                                                                                                    <geom size="0.00391667 0.014 0.00045" pos="0.00391667 0 0" type="box" />
                                                                                                                                    <body name="finger_2_segment_link_29" pos="0.00783333 0 0">
                                                                                                                                        <inertial pos="0 0 0" quat="0.5 0.5 -0.5 0.5" mass="0.00214808" diaginertia="1.84277e-07 1.40486e-07 4.40812e-08" />
                                                                                                                                        <joint name="finger_2_segment_joint_28" pos="0 0 0" axis="0 1 0" limited="true" range="-1 1" damping="0.01" />
                                                                                                                                        <geom size="0.00391667 0.014 0.00045" pos="0.00391667 0 0" type="box" contype="0" conaffinity="0" group="1" />
                                                                                                                                        <geom size="0.00391667 0.014 0.00045" pos="0.00391667 0 0" type="box" />
                                                                                                                                        <body name="finger_2_segment_link_30" pos="0.00783333 0 0">
                                                                                                                                            <inertial pos="0.00391667 0 0" quat="0.5 0.5 -0.5 0.5" mass="0.00429616" diaginertia="3.90668e-07 3.24764e-07 1.54067e-07" />
                                                                                                                                            <joint name="finger_2_segment_joint_29" pos="0 0 0" axis="0 1 0" limited="true" range="-1 1" damping="0.01" />
                                                                                                                                            <geom size="0.00391667 0.014 0.00045" pos="0.00391667 0 0" type="box" contype="0" conaffinity="0" group="1" />
                                                                                                                                            <geom size="0.00391667 0.014 0.00045" pos="0.00391667 0 0" type="box" />
                                                                                                                                            <geom size="0.01925 0.014 0.00045" pos="0.00783333 0 0.01925" quat="0.707107 0 -0.707107 0" type="box" contype="0" conaffinity="0" group="1" />
                                                                                                                                            <geom size="0.01925 0.014 0.00045" pos="0.00783333 0 0.01925" quat="0.707107 0 -0.707107 0" type="box" />
                                                                                                                                        </body>
                                                                                                                                    </body>
                                                                                                                                </body>
                                                                                                                            </body>
                                                                                                                        </body>
                                                                                                                    </body>
                                                                                                                </body>
                                                                                                            </body>
                                                                                                        </body>
                                                                                                    </body>
                                                                                                </body>
                                                                                            </body>
                                                                                        </body>
                                                                                    </body>
                                                                                </body>
                                                                            </body>
                                                                        </body>
                                                                    </body>
                                                                </body>
                                                            </body>
                                                        </body>
                                                    </body>
                                                </body>
                                            </body>
                                        </body>
                                    </body>
                                </body>
                            </body>
                        </body>
                    </body>
                </body>
            </body>
            <body name="finger_3_intermediate" pos="0 0 0" quat="-0.353553 -0.612372 0.353553 -0.612372">
                <inertial pos="0 0 0" quat="0.37634 0.403447 0.585982 0.593484" mass="0.1" diaginertia="0.000166494 0.00015418 3.54554e-05" />
                <joint name="finger_3_prismatic_joint" pos="0 0 0" axis="0 1 0" type="slide" limited="true" range="0.049 0.134" damping="1" />
                <geom type="mesh" contype="0" conaffinity="0" group="1" mesh="nut visual" />
                <geom type="mesh" mesh="nut collision" />
                <body name="finger_3" pos="0 0 0">
                    <inertial pos="0 0 0" quat="0.37634 0.403447 0.585982 0.593484" mass="0.1" diaginertia="0.000166494 0.00015418 3.54554e-05" />
                    <joint name="finger_3_revolute_joint" pos="0 0 0" axis="0 0 1" limited="true" range="-0.7 0.7" damping="1" />
                    <geom type="mesh" contype="0" conaffinity="0" group="1" mesh="platform only visual" />
                    <geom type="mesh" mesh="platform only collision" />
                    <body name="finger_3_segment_link_1" pos="0.129 -0.007 0" quat="0.707107 0.707107 0 0">
                        <inertial pos="0 0 0" quat="0.5 0.5 -0.5 0.5" mass="0.00214808" diaginertia="1.84277e-07 1.40486e-07 4.40812e-08" />
                        <joint name="finger_3_segment_joint_0" pos="0 0 0" axis="0 1 0" limited="true" range="-1 1" damping="0.01" />
                        <geom size="0.00391667 0.014 0.00045" pos="0.00391667 0 0" type="box" contype="0" conaffinity="0" group="1" />
                        <geom size="0.00391667 0.014 0.00045" pos="0.00391667 0 0" type="box" />
                        <body name="finger_3_segment_link_2" pos="0.00783333 0 0">
                            <inertial pos="0 0 0" quat="0.5 0.5 -0.5 0.5" mass="0.00214808" diaginertia="1.84277e-07 1.40486e-07 4.40812e-08" />
                            <joint name="finger_3_segment_joint_1" pos="0 0 0" axis="0 1 0" limited="true" range="-1 1" damping="0.01" />
                            <geom size="0.00391667 0.014 0.00045" pos="0.00391667 0 0" type="box" contype="0" conaffinity="0" group="1" />
                            <geom size="0.00391667 0.014 0.00045" pos="0.00391667 0 0" type="box" />
                            <body name="finger_3_segment_link_3" pos="0.00783333 0 0">
                                <inertial pos="0 0 0" quat="0.5 0.5 -0.5 0.5" mass="0.00214808" diaginertia="1.84277e-07 1.40486e-07 4.40812e-08" />
                                <joint name="finger_3_segment_joint_2" pos="0 0 0" axis="0 1 0" limited="true" range="-1 1" damping="0.01" />
                                <geom size="0.00391667 0.014 0.00045" pos="0.00391667 0 0" type="box" contype="0" conaffinity="0" group="1" />
                                <geom size="0.00391667 0.014 0.00045" pos="0.00391667 0 0" type="box" />
                                <body name="finger_3_segment_link_4" pos="0.00783333 0 0">
                                    <inertial pos="0 0 0" quat="0.5 0.5 -0.5 0.5" mass="0.00214808" diaginertia="1.84277e-07 1.40486e-07 4.40812e-08" />
                                    <joint name="finger_3_segment_joint_3" pos="0 0 0" axis="0 1 0" limited="true" range="-1 1" damping="0.01" />
                                    <geom size="0.00391667 0.014 0.00045" pos="0.00391667 0 0" type="box" contype="0" conaffinity="0" group="1" />
                                    <geom size="0.00391667 0.014 0.00045" pos="0.00391667 0 0" type="box" />
                                    <body name="finger_3_segment_link_5" pos="0.00783333 0 0">
                                        <inertial pos="0 0 0" quat="0.5 0.5 -0.5 0.5" mass="0.00214808" diaginertia="1.84277e-07 1.40486e-07 4.40812e-08" />
                                        <joint name="finger_3_segment_joint_4" pos="0 0 0" axis="0 1 0" limited="true" range="-1 1" damping="0.01" />
                                        <geom size="0.00391667 0.014 0.00045" pos="0.00391667 0 0" type="box" contype="0" conaffinity="0" group="1" />
                                        <geom size="0.00391667 0.014 0.00045" pos="0.00391667 0 0" type="box" />
                                        <body name="finger_3_segment_link_6" pos="0.00783333 0 0">
                                            <inertial pos="0 0 0" quat="0.5 0.5 -0.5 0.5" mass="0.00214808" diaginertia="1.84277e-07 1.40486e-07 4.40812e-08" />
                                            <joint name="finger_3_segment_joint_5" pos="0 0 0" axis="0 1 0" limited="true" range="-1 1" damping="0.01" />
                                            <geom size="0.00391667 0.014 0.00045" pos="0.00391667 0 0" type="box" contype="0" conaffinity="0" group="1" />
                                            <geom size="0.00391667 0.014 0.00045" pos="0.00391667 0 0" type="box" />
                                            <body name="finger_3_segment_link_7" pos="0.00783333 0 0">
                                                <inertial pos="0 0 0" quat="0.5 0.5 -0.5 0.5" mass="0.00214808" diaginertia="1.84277e-07 1.40486e-07 4.40812e-08" />
                                                <joint name="finger_3_segment_joint_6" pos="0 0 0" axis="0 1 0" limited="true" range="-1 1" damping="0.01" />
                                                <geom size="0.00391667 0.014 0.00045" pos="0.00391667 0 0" type="box" contype="0" conaffinity="0" group="1" />
                                                <geom size="0.00391667 0.014 0.00045" pos="0.00391667 0 0" type="box" />
                                                <body name="finger_3_segment_link_8" pos="0.00783333 0 0">
                                                    <inertial pos="0 0 0" quat="0.5 0.5 -0.5 0.5" mass="0.00214808" diaginertia="1.84277e-07 1.40486e-07 4.40812e-08" />
                                                    <joint name="finger_3_segment_joint_7" pos="0 0 0" axis="0 1 0" limited="true" range="-1 1" damping="0.01" />
                                                    <geom size="0.00391667 0.014 0.00045" pos="0.00391667 0 0" type="box" contype="0" conaffinity="0" group="1" />
                                                    <geom size="0.00391667 0.014 0.00045" pos="0.00391667 0 0" type="box" />
                                                    <body name="finger_3_segment_link_9" pos="0.00783333 0 0">
                                                        <inertial pos="0 0 0" quat="0.5 0.5 -0.5 0.5" mass="0.00214808" diaginertia="1.84277e-07 1.40486e-07 4.40812e-08" />
                                                        <joint name="finger_3_segment_joint_8" pos="0 0 0" axis="0 1 0" limited="true" range="-1 1" damping="0.01" />
                                                        <geom size="0.00391667 0.014 0.00045" pos="0.00391667 0 0" type="box" contype="0" conaffinity="0" group="1" />
                                                        <geom size="0.00391667 0.014 0.00045" pos="0.00391667 0 0" type="box" />
                                                        <body name="finger_3_segment_link_10" pos="0.00783333 0 0">
                                                            <inertial pos="0 0 0" quat="0.5 0.5 -0.5 0.5" mass="0.00214808" diaginertia="1.84277e-07 1.40486e-07 4.40812e-08" />
                                                            <joint name="finger_3_segment_joint_9" pos="0 0 0" axis="0 1 0" limited="true" range="-1 1" damping="0.01" />
                                                            <geom size="0.00391667 0.014 0.00045" pos="0.00391667 0 0" type="box" contype="0" conaffinity="0" group="1" />
                                                            <geom size="0.00391667 0.014 0.00045" pos="0.00391667 0 0" type="box" />
                                                            <body name="finger_3_segment_link_11" pos="0.00783333 0 0">
                                                                <inertial pos="0 0 0" quat="0.5 0.5 -0.5 0.5" mass="0.00214808" diaginertia="1.84277e-07 1.40486e-07 4.40812e-08" />
                                                                <joint name="finger_3_segment_joint_10" pos="0 0 0" axis="0 1 0" limited="true" range="-1 1" damping="0.01" />
                                                                <geom size="0.00391667 0.014 0.00045" pos="0.00391667 0 0" type="box" contype="0" conaffinity="0" group="1" />
                                                                <geom size="0.00391667 0.014 0.00045" pos="0.00391667 0 0" type="box" />
                                                                <body name="finger_3_segment_link_12" pos="0.00783333 0 0">
                                                                    <inertial pos="0 0 0" quat="0.5 0.5 -0.5 0.5" mass="0.00214808" diaginertia="1.84277e-07 1.40486e-07 4.40812e-08" />
                                                                    <joint name="finger_3_segment_joint_11" pos="0 0 0" axis="0 1 0" limited="true" range="-1 1" damping="0.01" />
                                                                    <geom size="0.00391667 0.014 0.00045" pos="0.00391667 0 0" type="box" contype="0" conaffinity="0" group="1" />
                                                                    <geom size="0.00391667 0.014 0.00045" pos="0.00391667 0 0" type="box" />
                                                                    <body name="finger_3_segment_link_13" pos="0.00783333 0 0">
                                                                        <inertial pos="0 0 0" quat="0.5 0.5 -0.5 0.5" mass="0.00214808" diaginertia="1.84277e-07 1.40486e-07 4.40812e-08" />
                                                                        <joint name="finger_3_segment_joint_12" pos="0 0 0" axis="0 1 0" limited="true" range="-1 1" damping="0.01" />
                                                                        <geom size="0.00391667 0.014 0.00045" pos="0.00391667 0 0" type="box" contype="0" conaffinity="0" group="1" />
                                                                        <geom size="0.00391667 0.014 0.00045" pos="0.00391667 0 0" type="box" />
                                                                        <body name="finger_3_segment_link_14" pos="0.00783333 0 0">
                                                                            <inertial pos="0 0 0" quat="0.5 0.5 -0.5 0.5" mass="0.00214808" diaginertia="1.84277e-07 1.40486e-07 4.40812e-08" />
                                                                            <joint name="finger_3_segment_joint_13" pos="0 0 0" axis="0 1 0" limited="true" range="-1 1" damping="0.01" />
                                                                            <geom size="0.00391667 0.014 0.00045" pos="0.00391667 0 0" type="box" contype="0" conaffinity="0" group="1" />
                                                                            <geom size="0.00391667 0.014 0.00045" pos="0.00391667 0 0" type="box" />
                                                                            <body name="finger_3_segment_link_15" pos="0.00783333 0 0">
                                                                                <inertial pos="0 0 0" quat="0.5 0.5 -0.5 0.5" mass="0.00214808" diaginertia="1.84277e-07 1.40486e-07 4.40812e-08" />
                                                                                <joint name="finger_3_segment_joint_14" pos="0 0 0" axis="0 1 0" limited="true" range="-1 1" damping="0.01" />
                                                                                <geom size="0.00391667 0.014 0.00045" pos="0.00391667 0 0" type="box" contype="0" conaffinity="0" group="1" />
                                                                                <geom size="0.00391667 0.014 0.00045" pos="0.00391667 0 0" type="box" />
                                                                                <body name="finger_3_segment_link_16" pos="0.00783333 0 0">
                                                                                    <inertial pos="0 0 0" quat="0.5 0.5 -0.5 0.5" mass="0.00214808" diaginertia="1.84277e-07 1.40486e-07 4.40812e-08" />
                                                                                    <joint name="finger_3_segment_joint_15" pos="0 0 0" axis="0 1 0" limited="true" range="-1 1" damping="0.01" />
                                                                                    <geom size="0.00391667 0.014 0.00045" pos="0.00391667 0 0" type="box" contype="0" conaffinity="0" group="1" />
                                                                                    <geom size="0.00391667 0.014 0.00045" pos="0.00391667 0 0" type="box" />
                                                                                    <body name="finger_3_segment_link_17" pos="0.00783333 0 0">
                                                                                        <inertial pos="0 0 0" quat="0.5 0.5 -0.5 0.5" mass="0.00214808" diaginertia="1.84277e-07 1.40486e-07 4.40812e-08" />
                                                                                        <joint name="finger_3_segment_joint_16" pos="0 0 0" axis="0 1 0" limited="true" range="-1 1" damping="0.01" />
                                                                                        <geom size="0.00391667 0.014 0.00045" pos="0.00391667 0 0" type="box" contype="0" conaffinity="0" group="1" />
                                                                                        <geom size="0.00391667 0.014 0.00045" pos="0.00391667 0 0" type="box" />
                                                                                        <body name="finger_3_segment_link_18" pos="0.00783333 0 0">
                                                                                            <inertial pos="0 0 0" quat="0.5 0.5 -0.5 0.5" mass="0.00214808" diaginertia="1.84277e-07 1.40486e-07 4.40812e-08" />
                                                                                            <joint name="finger_3_segment_joint_17" pos="0 0 0" axis="0 1 0" limited="true" range="-1 1" damping="0.01" />
                                                                                            <geom size="0.00391667 0.014 0.00045" pos="0.00391667 0 0" type="box" contype="0" conaffinity="0" group="1" />
                                                                                            <geom size="0.00391667 0.014 0.00045" pos="0.00391667 0 0" type="box" />
                                                                                            <body name="finger_3_segment_link_19" pos="0.00783333 0 0">
                                                                                                <inertial pos="0 0 0" quat="0.5 0.5 -0.5 0.5" mass="0.00214808" diaginertia="1.84277e-07 1.40486e-07 4.40812e-08" />
                                                                                                <joint name="finger_3_segment_joint_18" pos="0 0 0" axis="0 1 0" limited="true" range="-1 1" damping="0.01" />
                                                                                                <geom size="0.00391667 0.014 0.00045" pos="0.00391667 0 0" type="box" contype="0" conaffinity="0" group="1" />
                                                                                                <geom size="0.00391667 0.014 0.00045" pos="0.00391667 0 0" type="box" />
                                                                                                <body name="finger_3_segment_link_20" pos="0.00783333 0 0">
                                                                                                    <inertial pos="0 0 0" quat="0.5 0.5 -0.5 0.5" mass="0.00214808" diaginertia="1.84277e-07 1.40486e-07 4.40812e-08" />
                                                                                                    <joint name="finger_3_segment_joint_19" pos="0 0 0" axis="0 1 0" limited="true" range="-1 1" damping="0.01" />
                                                                                                    <geom size="0.00391667 0.014 0.00045" pos="0.00391667 0 0" type="box" contype="0" conaffinity="0" group="1" />
                                                                                                    <geom size="0.00391667 0.014 0.00045" pos="0.00391667 0 0" type="box" />
                                                                                                    <body name="finger_3_segment_link_21" pos="0.00783333 0 0">
                                                                                                        <inertial pos="0 0 0" quat="0.5 0.5 -0.5 0.5" mass="0.00214808" diaginertia="1.84277e-07 1.40486e-07 4.40812e-08" />
                                                                                                        <joint name="finger_3_segment_joint_20" pos="0 0 0" axis="0 1 0" limited="true" range="-1 1" damping="0.01" />
                                                                                                        <geom size="0.00391667 0.014 0.00045" pos="0.00391667 0 0" type="box" contype="0" conaffinity="0" group="1" />
                                                                                                        <geom size="0.00391667 0.014 0.00045" pos="0.00391667 0 0" type="box" />
                                                                                                        <body name="finger_3_segment_link_22" pos="0.00783333 0 0">
                                                                                                            <inertial pos="0 0 0" quat="0.5 0.5 -0.5 0.5" mass="0.00214808" diaginertia="1.84277e-07 1.40486e-07 4.40812e-08" />
                                                                                                            <joint name="finger_3_segment_joint_21" pos="0 0 0" axis="0 1 0" limited="true" range="-1 1" damping="0.01" />
                                                                                                            <geom size="0.00391667 0.014 0.00045" pos="0.00391667 0 0" type="box" contype="0" conaffinity="0" group="1" />
                                                                                                            <geom size="0.00391667 0.014 0.00045" pos="0.00391667 0 0" type="box" />
                                                                                                            <body name="finger_3_segment_link_23" pos="0.00783333 0 0">
                                                                                                                <inertial pos="0 0 0" quat="0.5 0.5 -0.5 0.5" mass="0.00214808" diaginertia="1.84277e-07 1.40486e-07 4.40812e-08" />
                                                                                                                <joint name="finger_3_segment_joint_22" pos="0 0 0" axis="0 1 0" limited="true" range="-1 1" damping="0.01" />
                                                                                                                <geom size="0.00391667 0.014 0.00045" pos="0.00391667 0 0" type="box" contype="0" conaffinity="0" group="1" />
                                                                                                                <geom size="0.00391667 0.014 0.00045" pos="0.00391667 0 0" type="box" />
                                                                                                                <body name="finger_3_segment_link_24" pos="0.00783333 0 0">
                                                                                                                    <inertial pos="0 0 0" quat="0.5 0.5 -0.5 0.5" mass="0.00214808" diaginertia="1.84277e-07 1.40486e-07 4.40812e-08" />
                                                                                                                    <joint name="finger_3_segment_joint_23" pos="0 0 0" axis="0 1 0" limited="true" range="-1 1" damping="0.01" />
                                                                                                                    <geom size="0.00391667 0.014 0.00045" pos="0.00391667 0 0" type="box" contype="0" conaffinity="0" group="1" />
                                                                                                                    <geom size="0.00391667 0.014 0.00045" pos="0.00391667 0 0" type="box" />
                                                                                                                    <body name="finger_3_segment_link_25" pos="0.00783333 0 0">
                                                                                                                        <inertial pos="0 0 0" quat="0.5 0.5 -0.5 0.5" mass="0.00214808" diaginertia="1.84277e-07 1.40486e-07 4.40812e-08" />
                                                                                                                        <joint name="finger_3_segment_joint_24" pos="0 0 0" axis="0 1 0" limited="true" range="-1 1" damping="0.01" />
                                                                                                                        <geom size="0.00391667 0.014 0.00045" pos="0.00391667 0 0" type="box" contype="0" conaffinity="0" group="1" />
                                                                                                                        <geom size="0.00391667 0.014 0.00045" pos="0.00391667 0 0" type="box" />
                                                                                                                        <body name="finger_3_segment_link_26" pos="0.00783333 0 0">
                                                                                                                            <inertial pos="0 0 0" quat="0.5 0.5 -0.5 0.5" mass="0.00214808" diaginertia="1.84277e-07 1.40486e-07 4.40812e-08" />
                                                                                                                            <joint name="finger_3_segment_joint_25" pos="0 0 0" axis="0 1 0" limited="true" range="-1 1" damping="0.01" />
                                                                                                                            <geom size="0.00391667 0.014 0.00045" pos="0.00391667 0 0" type="box" contype="0" conaffinity="0" group="1" />
                                                                                                                            <geom size="0.00391667 0.014 0.00045" pos="0.00391667 0 0" type="box" />
                                                                                                                            <body name="finger_3_segment_link_27" pos="0.00783333 0 0">
                                                                                                                                <inertial pos="0 0 0" quat="0.5 0.5 -0.5 0.5" mass="0.00214808" diaginertia="1.84277e-07 1.40486e-07 4.40812e-08" />
                                                                                                                                <joint name="finger_3_segment_joint_26" pos="0 0 0" axis="0 1 0" limited="true" range="-1 1" damping="0.01" />
                                                                                                                                <geom size="0.00391667 0.014 0.00045" pos="0.00391667 0 0" type="box" contype="0" conaffinity="0" group="1" />
                                                                                                                                <geom size="0.00391667 0.014 0.00045" pos="0.00391667 0 0" type="box" />
                                                                                                                                <body name="finger_3_segment_link_28" pos="0.00783333 0 0">
                                                                                                                                    <inertial pos="0 0 0" quat="0.5 0.5 -0.5 0.5" mass="0.00214808" diaginertia="1.84277e-07 1.40486e-07 4.40812e-08" />
                                                                                                                                    <joint name="finger_3_segment_joint_27" pos="0 0 0" axis="0 1 0" limited="true" range="-1 1" damping="0.01" />
                                                                                                                                    <geom size="0.00391667 0.014 0.00045" pos="0.00391667 0 0" type="box" contype="0" conaffinity="0" group="1" />
                                                                                                                                    <geom size="0.00391667 0.014 0.00045" pos="0.00391667 0 0" type="box" />
                                                                                                                                    <body name="finger_3_segment_link_29" pos="0.00783333 0 0">
                                                                                                                                        <inertial pos="0 0 0" quat="0.5 0.5 -0.5 0.5" mass="0.00214808" diaginertia="1.84277e-07 1.40486e-07 4.40812e-08" />
                                                                                                                                        <joint name="finger_3_segment_joint_28" pos="0 0 0" axis="0 1 0" limited="true" range="-1 1" damping="0.01" />
                                                                                                                                        <geom size="0.00391667 0.014 0.00045" pos="0.00391667 0 0" type="box" contype="0" conaffinity="0" group="1" />
                                                                                                                                        <geom size="0.00391667 0.014 0.00045" pos="0.00391667 0 0" type="box" />
                                                                                                                                        <body name="finger_3_segment_link_30" pos="0.00783333 0 0">
                                                                                                                                            <inertial pos="0.00391667 0 0" quat="0.5 0.5 -0.5 0.5" mass="0.00429616" diaginertia="3.90668e-07 3.24764e-07 1.54067e-07" />
                                                                                                                                            <joint name="finger_3_segment_joint_29" pos="0 0 0" axis="0 1 0" limited="true" range="-1 1" damping="0.01" />
                                                                                                                                            <geom size="0.00391667 0.014 0.00045" pos="0.00391667 0 0" type="box" contype="0" conaffinity="0" group="1" />
                                                                                                                                            <geom size="0.00391667 0.014 0.00045" pos="0.00391667 0 0" type="box" />
                                                                                                                                            <geom size="0.01925 0.014 0.00045" pos="0.00783333 0 0.01925" quat="0.707107 0 -0.707107 0" type="box" contype="0" conaffinity="0" group="1" />
                                                                                                                                            <geom size="0.01925 0.014 0.00045" pos="0.00783333 0 0.01925" quat="0.707107 0 -0.707107 0" type="box" />
                                                                                                                                        </body>
                                                                                                                                    </body>
                                                                                                                                </body>
                                                                                                                            </body>
                                                                                                                        </body>
                                                                                                                    </body>
                                                                                                                </body>
                                                                                                            </body>
                                                                                                        </body>
                                                                                                    </body>
                                                                                                </body>
                                                                                            </body>
                                                                                        </body>
                                                                                    </body>
                                                                                </body>
                                                                            </body>
                                                                        </body>
                                                                    </body>
                                                                </body>
                                                            </body>
                                                        </body>
                                                    </body>
                                                </body>
                                            </body>
                                        </body>
                                    </body>
                                </body>
                            </body>
                        </body>
                    </body>
                </body>
            </body>
            <body name="palm" pos="0 0 0" quat="0.707107 0 -0.707107 0">
                <inertial pos="0 0 0" mass="0.05" diaginertia="1e-05 1e-05 1e-05" />
                <joint name="palm_prismatic_joint" pos="0 0 0" axis="1 0 0" type="slide" limited="true" range="0 0.165" damping="1" />
                <geom type="mesh" contype="0" conaffinity="0" group="1" mesh="palm visual" />
                <geom type="mesh" mesh="palm collision" />
            </body>
        </body>
    </worldbody>
</mujoco>
