<?xml version='1.0' encoding='UTF-8'?>
<mujoco model="gripper_task">
    <compiler angle="radian" meshdir="./meshes_mujoco/"/>
    <size njmax="3200" nconmax="800"/>
    <asset>
        <mesh name="main body visual" file="main body visual.STL"/>
        <mesh name="nut visual" file="nut visual.STL"/>
        <mesh name="nut collision" file="nut collision.STL"/>
        <mesh name="platform only visual" file="platform only visual.STL"/>
        <mesh name="platform only collision" file="platform only collision.STL"/>
        <mesh name="palm visual" file="palm visual.STL"/>
        <mesh name="palm collision" file="palm collision.STL"/>
    <include file="mjcf_include/assets.xml"/></asset>
    <worldbody>
        <body name="gripper_base_link" pos="0 0 0.386" quat="0 1 0 0">
            <inertial pos="0 0 0.025" quat="-0.00978477 0.713334 -0.700715 -0.00752147" mass="1.5" diaginertia="0.010083 0.00995 0.00512698"/>
            <joint name="world_to_base" pos="0 0 0" axis="0 0 1" type="slide" limited="true" range="-1 1" damping="1"/>
            <geom type="mesh" contype="0" conaffinity="0" group="1" mesh="main body visual"/>
            <geom size="0.03 0.05" type="cylinder"/>
            <body name="finger_1_intermediate" pos="0 0 0" quat="0.707107 0 -0.707107 0">
                <inertial pos="0 0 0" quat="0.37634 0.403447 0.585982 0.593484" mass="0.1" diaginertia="0.000166494 0.00015418 3.54554e-05"/>
                <joint name="finger_1_prismatic_joint" pos="0 0 0" axis="0 1 0" type="slide" limited="true" range="0.049 0.134" damping="1"/>
                <geom type="mesh" contype="0" conaffinity="0" group="1" mesh="nut visual"/>
                <geom type="mesh" mesh="nut collision"/>
                <body name="finger_1" pos="0 0 0">
                    <inertial pos="0.00780979 -0.000423787 0" quat="0.296875 0.569165 0.423389 0.639264" mass="0.106444" diaginertia="0.00025779 0.000256016 4.76255e-05"/>
                    <joint name="finger_1_revolute_joint" pos="0 0 0" axis="0 0 1" limited="true" range="-0.7 0.7" damping="1"/>
                    <geom type="mesh" contype="0" conaffinity="0" group="1" mesh="platform only visual"/>
                    <geom type="mesh" mesh="platform only collision"/>
                    <geom size="0.01175 0.014 0.00045" pos="0.14075 -0.007 0" quat="0.707107 0.707107 0 0" type="box" contype="0" conaffinity="0" group="1"/>
                    <geom size="0.01175 0.014 0.00045" pos="0.14075 -0.007 0" quat="0.707107 0.707107 0 0" type="box"/>
                    <body name="finger_1_segment_link_2" pos="0.1525 -0.007 0" quat="0.707107 0.707107 0 0">
                        <inertial pos="0 0 0" quat="0 0.707107 0 0.707107" mass="0.00644424" diaginertia="1.6073e-06 1.18671e-06 4.21459e-07"/>
                        <joint name="finger_1_segment_joint_1" pos="0 0 0" axis="0 1 0" limited="true" range="-1 1" damping="0.01" stiffness="5"/>
                        <geom size="0.01175 0.014 0.00045" pos="0.01175 0 0" type="box" contype="0" conaffinity="0" group="1" name="finger_1_segment_link_2_geom_visual"/>
                        <geom size="0.01175 0.014 0.00045" pos="0.01175 0 0" type="box" name="finger_1_segment_link_2_geom_collision"/>
                        <body name="finger_1_segment_link_3" pos="0.0235 0 0">
                            <inertial pos="0 0 0" quat="0 0.707107 0 0.707107" mass="0.00644424" diaginertia="1.6073e-06 1.18671e-06 4.21459e-07"/>
                            <joint name="finger_1_segment_joint_2" pos="0 0 0" axis="0 1 0" limited="true" range="-1 1" damping="0.01" stiffness="5"/>
                            <geom size="0.01175 0.014 0.00045" pos="0.01175 0 0" type="box" contype="0" conaffinity="0" group="1" name="finger_1_segment_link_3_geom_visual"/>
                            <geom size="0.01175 0.014 0.00045" pos="0.01175 0 0" type="box" name="finger_1_segment_link_3_geom_collision"/>
                            <body name="finger_1_segment_link_4" pos="0.0235 0 0">
                                <inertial pos="0 0 0" quat="0 0.707107 0 0.707107" mass="0.00644424" diaginertia="1.6073e-06 1.18671e-06 4.21459e-07"/>
                                <joint name="finger_1_segment_joint_3" pos="0 0 0" axis="0 1 0" limited="true" range="-1 1" damping="0.01" stiffness="5"/>
                                <geom size="0.01175 0.014 0.00045" pos="0.01175 0 0" type="box" contype="0" conaffinity="0" group="1" name="finger_1_segment_link_4_geom_visual"/>
                                <geom size="0.01175 0.014 0.00045" pos="0.01175 0 0" type="box" name="finger_1_segment_link_4_geom_collision"/>
                                <body name="finger_1_segment_link_5" pos="0.0235 0 0">
                                    <inertial pos="0 0 0" quat="0 0.707107 0 0.707107" mass="0.00644424" diaginertia="1.6073e-06 1.18671e-06 4.21459e-07"/>
                                    <joint name="finger_1_segment_joint_4" pos="0 0 0" axis="0 1 0" limited="true" range="-1 1" damping="0.01" stiffness="5"/>
                                    <geom size="0.01175 0.014 0.00045" pos="0.01175 0 0" type="box" contype="0" conaffinity="0" group="1" name="finger_1_segment_link_5_geom_visual"/>
                                    <geom size="0.01175 0.014 0.00045" pos="0.01175 0 0" type="box" name="finger_1_segment_link_5_geom_collision"/>
                                    <body name="finger_1_segment_link_6" pos="0.0235 0 0">
                                        <inertial pos="0 0 0" quat="0 0.707107 0 0.707107" mass="0.00644424" diaginertia="1.6073e-06 1.18671e-06 4.21459e-07"/>
                                        <joint name="finger_1_segment_joint_5" pos="0 0 0" axis="0 1 0" limited="true" range="-1 1" damping="0.01" stiffness="5"/>
                                        <geom size="0.01175 0.014 0.00045" pos="0.01175 0 0" type="box" contype="0" conaffinity="0" group="1" name="finger_1_segment_link_6_geom_visual"/>
                                        <geom size="0.01175 0.014 0.00045" pos="0.01175 0 0" type="box" name="finger_1_segment_link_6_geom_collision"/>
                                        <body name="finger_1_segment_link_7" pos="0.0235 0 0">
                                            <inertial pos="0 0 0" quat="0 0.707107 0 0.707107" mass="0.00644424" diaginertia="1.6073e-06 1.18671e-06 4.21459e-07"/>
                                            <joint name="finger_1_segment_joint_6" pos="0 0 0" axis="0 1 0" limited="true" range="-1 1" damping="0.01" stiffness="5"/>
                                            <geom size="0.01175 0.014 0.00045" pos="0.01175 0 0" type="box" contype="0" conaffinity="0" group="1" name="finger_1_segment_link_7_geom_visual"/>
                                            <geom size="0.01175 0.014 0.00045" pos="0.01175 0 0" type="box" name="finger_1_segment_link_7_geom_collision"/>
                                            <body name="finger_1_segment_link_8" pos="0.0235 0 0">
                                                <inertial pos="0 0 0" quat="0 0.707107 0 0.707107" mass="0.00644424" diaginertia="1.6073e-06 1.18671e-06 4.21459e-07"/>
                                                <joint name="finger_1_segment_joint_7" pos="0 0 0" axis="0 1 0" limited="true" range="-1 1" damping="0.01" stiffness="5"/>
                                                <geom size="0.01175 0.014 0.00045" pos="0.01175 0 0" type="box" contype="0" conaffinity="0" group="1" name="finger_1_segment_link_8_geom_visual"/>
                                                <geom size="0.01175 0.014 0.00045" pos="0.01175 0 0" type="box" name="finger_1_segment_link_8_geom_collision"/>
                                                <body name="finger_1_segment_link_9" pos="0.0235 0 0">
                                                    <inertial pos="0 0 0" quat="0 0.707107 0 0.707107" mass="0.00644424" diaginertia="1.6073e-06 1.18671e-06 4.21459e-07"/>
                                                    <joint name="finger_1_segment_joint_8" pos="0 0 0" axis="0 1 0" limited="true" range="-1 1" damping="0.01" stiffness="5"/>
                                                    <geom size="0.01175 0.014 0.00045" pos="0.01175 0 0" type="box" contype="0" conaffinity="0" group="1" name="finger_1_segment_link_9_geom_visual"/>
                                                    <geom size="0.01175 0.014 0.00045" pos="0.01175 0 0" type="box" name="finger_1_segment_link_9_geom_collision"/>
                                                    <body name="finger_1_segment_link_10" pos="0.0235 0 0">
                                                        <inertial pos="0.01175 0 0" quat="0.5 0.5 0.5 0.5" mass="0.0128885" diaginertia="4.15284e-06 3.80818e-06 2.02876e-06"/>
                                                        <joint name="finger_1_segment_joint_9" pos="0 0 0" axis="0 1 0" limited="true" range="-1 1" damping="0.01" stiffness="5"/>
                                                        <geom size="0.01175 0.014 0.00045" pos="0.01175 0 0" type="box" contype="0" conaffinity="0" group="1" name="finger_1_segment_link_10_geom_visual"/>
                                                        <geom size="0.01175 0.014 0.00045" pos="0.01175 0 0" type="box" name="finger_1_segment_link_10_geom_collision"/>
                                                        <geom size="0.01925 0.014 0.00045" pos="0.0235 0 0.01925" quat="0.707107 0 -0.707107 0" type="box" contype="0" conaffinity="0" group="1" name="finger_1_segment_link_10_geom_hook_visual"/>
                                                        <geom size="0.01925 0.014 0.00045" pos="0.0235 0 0.01925" quat="0.707107 0 -0.707107 0" type="box" name="finger_1_segment_link_10_geom_hook_collision"/>
                                                    </body>
                                                </body>
                                            </body>
                                        </body>
                                    </body>
                                </body>
                            </body>
                        </body>
                    </body>
                </body>
            </body>
            <body name="finger_2_intermediate" pos="0 0 0" quat="0.353553 -0.612372 -0.353553 -0.612372">
                <inertial pos="0 0 0" quat="0.37634 0.403447 0.585982 0.593484" mass="0.1" diaginertia="0.000166494 0.00015418 3.54554e-05"/>
                <joint name="finger_2_prismatic_joint" pos="0 0 0" axis="0 1 0" type="slide" limited="true" range="0.049 0.134" damping="1"/>
                <geom type="mesh" contype="0" conaffinity="0" group="1" mesh="nut visual"/>
                <geom type="mesh" mesh="nut collision"/>
                <body name="finger_2" pos="0 0 0">
                    <inertial pos="0.00780979 -0.000423787 0" quat="0.296875 0.569165 0.423389 0.639264" mass="0.106444" diaginertia="0.00025779 0.000256016 4.76255e-05"/>
                    <joint name="finger_2_revolute_joint" pos="0 0 0" axis="0 0 1" limited="true" range="-0.7 0.7" damping="1"/>
                    <geom type="mesh" contype="0" conaffinity="0" group="1" mesh="platform only visual"/>
                    <geom type="mesh" mesh="platform only collision"/>
                    <geom size="0.01175 0.014 0.00045" pos="0.14075 -0.007 0" quat="0.707107 0.707107 0 0" type="box" contype="0" conaffinity="0" group="1"/>
                    <geom size="0.01175 0.014 0.00045" pos="0.14075 -0.007 0" quat="0.707107 0.707107 0 0" type="box"/>
                    <body name="finger_2_segment_link_2" pos="0.1525 -0.007 0" quat="0.707107 0.707107 0 0">
                        <inertial pos="0 0 0" quat="0 0.707107 0 0.707107" mass="0.00644424" diaginertia="1.6073e-06 1.18671e-06 4.21459e-07"/>
                        <joint name="finger_2_segment_joint_1" pos="0 0 0" axis="0 1 0" limited="true" range="-1 1" damping="0.01" stiffness="5"/>
                        <geom size="0.01175 0.014 0.00045" pos="0.01175 0 0" type="box" contype="0" conaffinity="0" group="1" name="finger_2_segment_link_2_geom_visual"/>
                        <geom size="0.01175 0.014 0.00045" pos="0.01175 0 0" type="box" name="finger_2_segment_link_2_geom_collision"/>
                        <body name="finger_2_segment_link_3" pos="0.0235 0 0">
                            <inertial pos="0 0 0" quat="0 0.707107 0 0.707107" mass="0.00644424" diaginertia="1.6073e-06 1.18671e-06 4.21459e-07"/>
                            <joint name="finger_2_segment_joint_2" pos="0 0 0" axis="0 1 0" limited="true" range="-1 1" damping="0.01" stiffness="5"/>
                            <geom size="0.01175 0.014 0.00045" pos="0.01175 0 0" type="box" contype="0" conaffinity="0" group="1" name="finger_2_segment_link_3_geom_visual"/>
                            <geom size="0.01175 0.014 0.00045" pos="0.01175 0 0" type="box" name="finger_2_segment_link_3_geom_collision"/>
                            <body name="finger_2_segment_link_4" pos="0.0235 0 0">
                                <inertial pos="0 0 0" quat="0 0.707107 0 0.707107" mass="0.00644424" diaginertia="1.6073e-06 1.18671e-06 4.21459e-07"/>
                                <joint name="finger_2_segment_joint_3" pos="0 0 0" axis="0 1 0" limited="true" range="-1 1" damping="0.01" stiffness="5"/>
                                <geom size="0.01175 0.014 0.00045" pos="0.01175 0 0" type="box" contype="0" conaffinity="0" group="1" name="finger_2_segment_link_4_geom_visual"/>
                                <geom size="0.01175 0.014 0.00045" pos="0.01175 0 0" type="box" name="finger_2_segment_link_4_geom_collision"/>
                                <body name="finger_2_segment_link_5" pos="0.0235 0 0">
                                    <inertial pos="0 0 0" quat="0 0.707107 0 0.707107" mass="0.00644424" diaginertia="1.6073e-06 1.18671e-06 4.21459e-07"/>
                                    <joint name="finger_2_segment_joint_4" pos="0 0 0" axis="0 1 0" limited="true" range="-1 1" damping="0.01" stiffness="5"/>
                                    <geom size="0.01175 0.014 0.00045" pos="0.01175 0 0" type="box" contype="0" conaffinity="0" group="1" name="finger_2_segment_link_5_geom_visual"/>
                                    <geom size="0.01175 0.014 0.00045" pos="0.01175 0 0" type="box" name="finger_2_segment_link_5_geom_collision"/>
                                    <body name="finger_2_segment_link_6" pos="0.0235 0 0">
                                        <inertial pos="0 0 0" quat="0 0.707107 0 0.707107" mass="0.00644424" diaginertia="1.6073e-06 1.18671e-06 4.21459e-07"/>
                                        <joint name="finger_2_segment_joint_5" pos="0 0 0" axis="0 1 0" limited="true" range="-1 1" damping="0.01" stiffness="5"/>
                                        <geom size="0.01175 0.014 0.00045" pos="0.01175 0 0" type="box" contype="0" conaffinity="0" group="1" name="finger_2_segment_link_6_geom_visual"/>
                                        <geom size="0.01175 0.014 0.00045" pos="0.01175 0 0" type="box" name="finger_2_segment_link_6_geom_collision"/>
                                        <body name="finger_2_segment_link_7" pos="0.0235 0 0">
                                            <inertial pos="0 0 0" quat="0 0.707107 0 0.707107" mass="0.00644424" diaginertia="1.6073e-06 1.18671e-06 4.21459e-07"/>
                                            <joint name="finger_2_segment_joint_6" pos="0 0 0" axis="0 1 0" limited="true" range="-1 1" damping="0.01" stiffness="5"/>
                                            <geom size="0.01175 0.014 0.00045" pos="0.01175 0 0" type="box" contype="0" conaffinity="0" group="1" name="finger_2_segment_link_7_geom_visual"/>
                                            <geom size="0.01175 0.014 0.00045" pos="0.01175 0 0" type="box" name="finger_2_segment_link_7_geom_collision"/>
                                            <body name="finger_2_segment_link_8" pos="0.0235 0 0">
                                                <inertial pos="0 0 0" quat="0 0.707107 0 0.707107" mass="0.00644424" diaginertia="1.6073e-06 1.18671e-06 4.21459e-07"/>
                                                <joint name="finger_2_segment_joint_7" pos="0 0 0" axis="0 1 0" limited="true" range="-1 1" damping="0.01" stiffness="5"/>
                                                <geom size="0.01175 0.014 0.00045" pos="0.01175 0 0" type="box" contype="0" conaffinity="0" group="1" name="finger_2_segment_link_8_geom_visual"/>
                                                <geom size="0.01175 0.014 0.00045" pos="0.01175 0 0" type="box" name="finger_2_segment_link_8_geom_collision"/>
                                                <body name="finger_2_segment_link_9" pos="0.0235 0 0">
                                                    <inertial pos="0 0 0" quat="0 0.707107 0 0.707107" mass="0.00644424" diaginertia="1.6073e-06 1.18671e-06 4.21459e-07"/>
                                                    <joint name="finger_2_segment_joint_8" pos="0 0 0" axis="0 1 0" limited="true" range="-1 1" damping="0.01" stiffness="5"/>
                                                    <geom size="0.01175 0.014 0.00045" pos="0.01175 0 0" type="box" contype="0" conaffinity="0" group="1" name="finger_2_segment_link_9_geom_visual"/>
                                                    <geom size="0.01175 0.014 0.00045" pos="0.01175 0 0" type="box" name="finger_2_segment_link_9_geom_collision"/>
                                                    <body name="finger_2_segment_link_10" pos="0.0235 0 0">
                                                        <inertial pos="0.01175 0 0" quat="0.5 0.5 0.5 0.5" mass="0.0128885" diaginertia="4.15284e-06 3.80818e-06 2.02876e-06"/>
                                                        <joint name="finger_2_segment_joint_9" pos="0 0 0" axis="0 1 0" limited="true" range="-1 1" damping="0.01" stiffness="5"/>
                                                        <geom size="0.01175 0.014 0.00045" pos="0.01175 0 0" type="box" contype="0" conaffinity="0" group="1" name="finger_2_segment_link_10_geom_visual"/>
                                                        <geom size="0.01175 0.014 0.00045" pos="0.01175 0 0" type="box" name="finger_2_segment_link_10_geom_collision"/>
                                                        <geom size="0.01925 0.014 0.00045" pos="0.0235 0 0.01925" quat="0.707107 0 -0.707107 0" type="box" contype="0" conaffinity="0" group="1" name="finger_2_segment_link_10_geom_hook_visual"/>
                                                        <geom size="0.01925 0.014 0.00045" pos="0.0235 0 0.01925" quat="0.707107 0 -0.707107 0" type="box" name="finger_2_segment_link_10_geom_hook_collision"/>
                                                    </body>
                                                </body>
                                            </body>
                                        </body>
                                    </body>
                                </body>
                            </body>
                        </body>
                    </body>
                </body>
            </body>
            <body name="finger_3_intermediate" pos="0 0 0" quat="-0.353553 -0.612372 0.353553 -0.612372">
                <inertial pos="0 0 0" quat="0.37634 0.403447 0.585982 0.593484" mass="0.1" diaginertia="0.000166494 0.00015418 3.54554e-05"/>
                <joint name="finger_3_prismatic_joint" pos="0 0 0" axis="0 1 0" type="slide" limited="true" range="0.049 0.134" damping="1"/>
                <geom type="mesh" contype="0" conaffinity="0" group="1" mesh="nut visual"/>
                <geom type="mesh" mesh="nut collision"/>
                <body name="finger_3" pos="0 0 0">
                    <inertial pos="0.00780979 -0.000423787 0" quat="0.296875 0.569165 0.423389 0.639264" mass="0.106444" diaginertia="0.00025779 0.000256016 4.76255e-05"/>
                    <joint name="finger_3_revolute_joint" pos="0 0 0" axis="0 0 1" limited="true" range="-0.7 0.7" damping="1"/>
                    <geom type="mesh" contype="0" conaffinity="0" group="1" mesh="platform only visual"/>
                    <geom type="mesh" mesh="platform only collision"/>
                    <geom size="0.01175 0.014 0.00045" pos="0.14075 -0.007 0" quat="0.707107 0.707107 0 0" type="box" contype="0" conaffinity="0" group="1"/>
                    <geom size="0.01175 0.014 0.00045" pos="0.14075 -0.007 0" quat="0.707107 0.707107 0 0" type="box"/>
                    <body name="finger_3_segment_link_2" pos="0.1525 -0.007 0" quat="0.707107 0.707107 0 0">
                        <inertial pos="0 0 0" quat="0 0.707107 0 0.707107" mass="0.00644424" diaginertia="1.6073e-06 1.18671e-06 4.21459e-07"/>
                        <joint name="finger_3_segment_joint_1" pos="0 0 0" axis="0 1 0" limited="true" range="-1 1" damping="0.01" stiffness="5"/>
                        <geom size="0.01175 0.014 0.00045" pos="0.01175 0 0" type="box" contype="0" conaffinity="0" group="1" name="finger_3_segment_link_2_geom_visual"/>
                        <geom size="0.01175 0.014 0.00045" pos="0.01175 0 0" type="box" name="finger_3_segment_link_2_geom_collision"/>
                        <body name="finger_3_segment_link_3" pos="0.0235 0 0">
                            <inertial pos="0 0 0" quat="0 0.707107 0 0.707107" mass="0.00644424" diaginertia="1.6073e-06 1.18671e-06 4.21459e-07"/>
                            <joint name="finger_3_segment_joint_2" pos="0 0 0" axis="0 1 0" limited="true" range="-1 1" damping="0.01" stiffness="5"/>
                            <geom size="0.01175 0.014 0.00045" pos="0.01175 0 0" type="box" contype="0" conaffinity="0" group="1" name="finger_3_segment_link_3_geom_visual"/>
                            <geom size="0.01175 0.014 0.00045" pos="0.01175 0 0" type="box" name="finger_3_segment_link_3_geom_collision"/>
                            <body name="finger_3_segment_link_4" pos="0.0235 0 0">
                                <inertial pos="0 0 0" quat="0 0.707107 0 0.707107" mass="0.00644424" diaginertia="1.6073e-06 1.18671e-06 4.21459e-07"/>
                                <joint name="finger_3_segment_joint_3" pos="0 0 0" axis="0 1 0" limited="true" range="-1 1" damping="0.01" stiffness="5"/>
                                <geom size="0.01175 0.014 0.00045" pos="0.01175 0 0" type="box" contype="0" conaffinity="0" group="1" name="finger_3_segment_link_4_geom_visual"/>
                                <geom size="0.01175 0.014 0.00045" pos="0.01175 0 0" type="box" name="finger_3_segment_link_4_geom_collision"/>
                                <body name="finger_3_segment_link_5" pos="0.0235 0 0">
                                    <inertial pos="0 0 0" quat="0 0.707107 0 0.707107" mass="0.00644424" diaginertia="1.6073e-06 1.18671e-06 4.21459e-07"/>
                                    <joint name="finger_3_segment_joint_4" pos="0 0 0" axis="0 1 0" limited="true" range="-1 1" damping="0.01" stiffness="5"/>
                                    <geom size="0.01175 0.014 0.00045" pos="0.01175 0 0" type="box" contype="0" conaffinity="0" group="1" name="finger_3_segment_link_5_geom_visual"/>
                                    <geom size="0.01175 0.014 0.00045" pos="0.01175 0 0" type="box" name="finger_3_segment_link_5_geom_collision"/>
                                    <body name="finger_3_segment_link_6" pos="0.0235 0 0">
                                        <inertial pos="0 0 0" quat="0 0.707107 0 0.707107" mass="0.00644424" diaginertia="1.6073e-06 1.18671e-06 4.21459e-07"/>
                                        <joint name="finger_3_segment_joint_5" pos="0 0 0" axis="0 1 0" limited="true" range="-1 1" damping="0.01" stiffness="5"/>
                                        <geom size="0.01175 0.014 0.00045" pos="0.01175 0 0" type="box" contype="0" conaffinity="0" group="1" name="finger_3_segment_link_6_geom_visual"/>
                                        <geom size="0.01175 0.014 0.00045" pos="0.01175 0 0" type="box" name="finger_3_segment_link_6_geom_collision"/>
                                        <body name="finger_3_segment_link_7" pos="0.0235 0 0">
                                            <inertial pos="0 0 0" quat="0 0.707107 0 0.707107" mass="0.00644424" diaginertia="1.6073e-06 1.18671e-06 4.21459e-07"/>
                                            <joint name="finger_3_segment_joint_6" pos="0 0 0" axis="0 1 0" limited="true" range="-1 1" damping="0.01" stiffness="5"/>
                                            <geom size="0.01175 0.014 0.00045" pos="0.01175 0 0" type="box" contype="0" conaffinity="0" group="1" name="finger_3_segment_link_7_geom_visual"/>
                                            <geom size="0.01175 0.014 0.00045" pos="0.01175 0 0" type="box" name="finger_3_segment_link_7_geom_collision"/>
                                            <body name="finger_3_segment_link_8" pos="0.0235 0 0">
                                                <inertial pos="0 0 0" quat="0 0.707107 0 0.707107" mass="0.00644424" diaginertia="1.6073e-06 1.18671e-06 4.21459e-07"/>
                                                <joint name="finger_3_segment_joint_7" pos="0 0 0" axis="0 1 0" limited="true" range="-1 1" damping="0.01" stiffness="5"/>
                                                <geom size="0.01175 0.014 0.00045" pos="0.01175 0 0" type="box" contype="0" conaffinity="0" group="1" name="finger_3_segment_link_8_geom_visual"/>
                                                <geom size="0.01175 0.014 0.00045" pos="0.01175 0 0" type="box" name="finger_3_segment_link_8_geom_collision"/>
                                                <body name="finger_3_segment_link_9" pos="0.0235 0 0">
                                                    <inertial pos="0 0 0" quat="0 0.707107 0 0.707107" mass="0.00644424" diaginertia="1.6073e-06 1.18671e-06 4.21459e-07"/>
                                                    <joint name="finger_3_segment_joint_8" pos="0 0 0" axis="0 1 0" limited="true" range="-1 1" damping="0.01" stiffness="5"/>
                                                    <geom size="0.01175 0.014 0.00045" pos="0.01175 0 0" type="box" contype="0" conaffinity="0" group="1" name="finger_3_segment_link_9_geom_visual"/>
                                                    <geom size="0.01175 0.014 0.00045" pos="0.01175 0 0" type="box" name="finger_3_segment_link_9_geom_collision"/>
                                                    <body name="finger_3_segment_link_10" pos="0.0235 0 0">
                                                        <inertial pos="0.01175 0 0" quat="0.5 0.5 0.5 0.5" mass="0.0128885" diaginertia="4.15284e-06 3.80818e-06 2.02876e-06"/>
                                                        <joint name="finger_3_segment_joint_9" pos="0 0 0" axis="0 1 0" limited="true" range="-1 1" damping="0.01" stiffness="5"/>
                                                        <geom size="0.01175 0.014 0.00045" pos="0.01175 0 0" type="box" contype="0" conaffinity="0" group="1" name="finger_3_segment_link_10_geom_visual"/>
                                                        <geom size="0.01175 0.014 0.00045" pos="0.01175 0 0" type="box" name="finger_3_segment_link_10_geom_collision"/>
                                                        <geom size="0.01925 0.014 0.00045" pos="0.0235 0 0.01925" quat="0.707107 0 -0.707107 0" type="box" contype="0" conaffinity="0" group="1" name="finger_3_segment_link_10_geom_hook_visual"/>
                                                        <geom size="0.01925 0.014 0.00045" pos="0.0235 0 0.01925" quat="0.707107 0 -0.707107 0" type="box" name="finger_3_segment_link_10_geom_hook_collision"/>
                                                    </body>
                                                </body>
                                            </body>
                                        </body>
                                    </body>
                                </body>
                            </body>
                        </body>
                    </body>
                </body>
            </body>
            <body name="palm" pos="0 0 0" quat="0.707107 0 -0.707107 0">
                <inertial pos="0 0 0" mass="0.05" diaginertia="1e-05 1e-05 1e-05"/>
                <joint name="palm_prismatic_joint" pos="0 0 0" axis="1 0 0" type="slide" limited="true" range="0 0.165" damping="1"/>
                <geom type="mesh" contype="0" conaffinity="0" group="1" mesh="palm visual" name="palm_geom_visual"/>
                <geom type="mesh" mesh="palm collision" name="palm_geom_collision"/>
            </body>
        <site name="force sensor site" type="sphere" rgba="0 0 0 0" size="0.005 0.005 0.005" pos="0 0 0" quat="0 0 0 1"/></body>
    <include file="mjcf_include/objects.xml"/></worldbody>
<keyframe>
    <key name="initial pose" time="0" qpos="0.0 0.13133 0.0 0 0 0 0 0 0 0 0 0  0.13133 0.0 0 0 0 0 0 0 0 0 0  0.13133 0.0 0 0 0 0 0 0 0 0 0  0.00488  -4.75 2.0 0.035 0 0 0 1 -4.25 2.0 0.0352941176471 0 0 0 1 -3.75 2.0 0.0355882352941 0 0 0 1 -3.25 2.0 0.0358823529412 0 0 0 1 -2.75 2.0 0.0361764705882 0 0 0 1 -2.25 2.0 0.0364705882353 0 0 0 1 -1.75 2.0 0.0367647058824 0 0 0 1 -1.25 2.0 0.0370588235294 0 0 0 1 -0.75 2.0 0.0373529411765 0 0 0 1 -0.25 2.0 0.0376470588235 0 0 0 1 0.25 2.0 0.0379411764706 0 0 0 1 0.75 2.0 0.0382352941176 0 0 0 1 1.25 2.0 0.0385294117647 0 0 0 1 1.75 2.0 0.0388235294118 0 0 0 1 2.25 2.0 0.0391176470588 0 0 0 1 2.75 2.0 0.0394117647059 0 0 0 1 3.25 2.0 0.0397058823529 0 0 0 1 3.75 2.0 0.04 0 0 0 1 4.25 2.0 0.0402941176471 0 0 0 1 4.75 2.0 0.0405882352941 0 0 0 1 -4.75 2.5 0.0408823529412 0 0 0 1 -4.25 2.5 0.0411764705882 0 0 0 1 -3.75 2.5 0.0414705882353 0 0 0 1 -3.25 2.5 0.0417647058824 0 0 0 1 -2.75 2.5 0.0420588235294 0 0 0 1 -2.25 2.5 0.0423529411765 0 0 0 1 -1.75 2.5 0.0426470588235 0 0 0 1 -1.25 2.5 0.0429411764706 0 0 0 1 -0.75 2.5 0.0432352941176 0 0 0 1 -0.25 2.5 0.0435294117647 0 0 0 1 0.25 2.5 0.0438235294118 0 0 0 1 0.75 2.5 0.0441176470588 0 0 0 1 1.25 2.5 0.0444117647059 0 0 0 1 1.75 2.5 0.0447058823529 0 0 0 1 2.25 2.5 0.045 0 0 0 1 2.75 2.5 0.0452941176471 0 0 0 1 3.25 2.5 0.0455882352941 0 0 0 1 3.75 2.5 0.0458823529412 0 0 0 1 4.25 2.5 0.0461764705882 0 0 0 1 4.75 2.5 0.0464705882353 0 0 0 1 -4.75 3.0 0.0467647058824 0 0 0 1 -4.25 3.0 0.0470588235294 0 0 0 1 -3.75 3.0 0.0473529411765 0 0 0 1 -3.25 3.0 0.0476470588235 0 0 0 1 -2.75 3.0 0.0479411764706 0 0 0 1 -2.25 3.0 0.0482352941176 0 0 0 1 -1.75 3.0 0.0485294117647 0 0 0 1 -1.25 3.0 0.0488235294118 0 0 0 1 -0.75 3.0 0.0491176470588 0 0 0 1 -0.25 3.0 0.0494117647059 0 0 0 1 0.25 3.0 0.0497058823529 0 0 0 1 0.75 3.0 0.05 0 0 0 1 1.25 3.0 0.0502941176471 0 0 0 1 1.75 3.0 0.0505882352941 0 0 0 1 2.25 3.0 0.0508823529412 0 0 0 1 2.75 3.0 0.0511764705882 0 0 0 1 3.25 3.0 0.0514705882353 0 0 0 1 3.75 3.0 0.0517647058824 0 0 0 1 4.25 3.0 0.0520588235294 0 0 0 1 4.75 3.0 0.0523529411765 0 0 0 1 -4.75 3.5 0.0526470588235 0 0 0 1 -4.25 3.5 0.0529411764706 0 0 0 1 -3.75 3.5 0.0532352941176 0 0 0 1 -3.25 3.5 0.0535294117647 0 0 0 1 -2.75 3.5 0.0538235294118 0 0 0 1 -2.25 3.5 0.0541176470588 0 0 0 1 -1.75 3.5 0.0544117647059 0 0 0 1 -1.25 3.5 0.0547058823529 0 0 0 1 -0.75 3.5 0.055 0 0 0 1 -0.25 3.5 0.0552941176471 0 0 0 1 0.25 3.5 0.0555882352941 0 0 0 1 0.75 3.5 0.0558823529412 0 0 0 1 1.25 3.5 0.0561764705882 0 0 0 1 1.75 3.5 0.0564705882353 0 0 0 1 2.25 3.5 0.0567647058824 0 0 0 1 2.75 3.5 0.0570588235294 0 0 0 1 3.25 3.5 0.0573529411765 0 0 0 1 3.75 3.5 0.0576470588235 0 0 0 1 4.25 3.5 0.0579411764706 0 0 0 1 4.75 3.5 0.0582352941176 0 0 0 1 -4.75 4.0 0.0585294117647 0 0 0 1 -4.25 4.0 0.0588235294118 0 0 0 1 -3.75 4.0 0.0591176470588 0 0 0 1 -3.25 4.0 0.0594117647059 0 0 0 1 -2.75 4.0 0.0597058823529 0 0 0 1 -2.25 4.0 0.06 0 0 0 1 -1.75 4.0 0.0602941176471 0 0 0 1 -1.25 4.0 0.0605882352941 0 0 0 1 -0.75 4.0 0.0608823529412 0 0 0 1 -0.25 4.0 0.0611764705882 0 0 0 1 0.25 4.0 0.0614705882353 0 0 0 1 0.75 4.0 0.0617647058824 0 0 0 1 1.25 4.0 0.0620588235294 0 0 0 1 1.75 4.0 0.0623529411765 0 0 0 1 2.25 4.0 0.0626470588235 0 0 0 1 2.75 4.0 0.0629411764706 0 0 0 1 3.25 4.0 0.0632352941176 0 0 0 1 3.75 4.0 0.0635294117647 0 0 0 1 4.25 4.0 0.0638235294118 0 0 0 1 4.75 4.0 0.0641176470588 0 0 0 1 -4.75 4.5 0.0644117647059 0 0 0 1 -4.25 4.5 0.0647058823529 0 0 0 1 -3.75 4.5 0.065 0 0 0 1 -3.25 4.5 0.0652941176471 0 0 0 1 -2.75 4.5 0.0655882352941 0 0 0 1 -2.25 4.5 0.0658823529412 0 0 0 1 -1.75 4.5 0.0661764705882 0 0 0 1 -1.25 4.5 0.0664705882353 0 0 0 1 -0.75 4.5 0.0667647058824 0 0 0 1 -0.25 4.5 0.0670588235294 0 0 0 1 0.25 4.5 0.0673529411765 0 0 0 1 0.75 4.5 0.0676470588235 0 0 0 1 1.25 4.5 0.0679411764706 0 0 0 1 1.75 4.5 0.0682352941176 0 0 0 1 2.25 4.5 0.0685294117647 0 0 0 1 2.75 4.5 0.0688235294118 0 0 0 1 3.25 4.5 0.0691176470588 0 0 0 1 3.75 4.5 0.0694117647059 0 0 0 1 4.25 4.5 0.0697058823529 0 0 0 1 4.75 4.5 0.07 0 0 0 1"/>
  </keyframe><actuator>
    
  <motor name="world_to_base_actuator" joint="world_to_base"/>

    
  <motor name="finger_1_prismatic_joint_actuator" joint="finger_1_prismatic_joint"/>

  <motor name="finger_1_revolute_joint_actuator" joint="finger_1_revolute_joint"/>

  <motor name="finger_2_prismatic_joint_actuator" joint="finger_2_prismatic_joint"/>

  <motor name="finger_2_revolute_joint_actuator" joint="finger_2_revolute_joint"/>

  <motor name="finger_3_prismatic_joint_actuator" joint="finger_3_prismatic_joint"/>

  <motor name="finger_3_revolute_joint_actuator" joint="finger_3_revolute_joint"/>

  <motor name="palm_prismatic_joint_actuator" joint="palm_prismatic_joint"/>

    
  <motor name="finger_1_segment_joint_1_actuator" joint="finger_1_segment_joint_1"/>

  <motor name="finger_1_segment_joint_2_actuator" joint="finger_1_segment_joint_2"/>

  <motor name="finger_1_segment_joint_3_actuator" joint="finger_1_segment_joint_3"/>

  <motor name="finger_1_segment_joint_4_actuator" joint="finger_1_segment_joint_4"/>

  <motor name="finger_1_segment_joint_5_actuator" joint="finger_1_segment_joint_5"/>

  <motor name="finger_1_segment_joint_6_actuator" joint="finger_1_segment_joint_6"/>

  <motor name="finger_1_segment_joint_7_actuator" joint="finger_1_segment_joint_7"/>

  <motor name="finger_1_segment_joint_8_actuator" joint="finger_1_segment_joint_8"/>

  <motor name="finger_1_segment_joint_9_actuator" joint="finger_1_segment_joint_9"/>

  <motor name="finger_2_segment_joint_1_actuator" joint="finger_2_segment_joint_1"/>

  <motor name="finger_2_segment_joint_2_actuator" joint="finger_2_segment_joint_2"/>

  <motor name="finger_2_segment_joint_3_actuator" joint="finger_2_segment_joint_3"/>

  <motor name="finger_2_segment_joint_4_actuator" joint="finger_2_segment_joint_4"/>

  <motor name="finger_2_segment_joint_5_actuator" joint="finger_2_segment_joint_5"/>

  <motor name="finger_2_segment_joint_6_actuator" joint="finger_2_segment_joint_6"/>

  <motor name="finger_2_segment_joint_7_actuator" joint="finger_2_segment_joint_7"/>

  <motor name="finger_2_segment_joint_8_actuator" joint="finger_2_segment_joint_8"/>

  <motor name="finger_2_segment_joint_9_actuator" joint="finger_2_segment_joint_9"/>

  <motor name="finger_3_segment_joint_1_actuator" joint="finger_3_segment_joint_1"/>

  <motor name="finger_3_segment_joint_2_actuator" joint="finger_3_segment_joint_2"/>

  <motor name="finger_3_segment_joint_3_actuator" joint="finger_3_segment_joint_3"/>

  <motor name="finger_3_segment_joint_4_actuator" joint="finger_3_segment_joint_4"/>

  <motor name="finger_3_segment_joint_5_actuator" joint="finger_3_segment_joint_5"/>

  <motor name="finger_3_segment_joint_6_actuator" joint="finger_3_segment_joint_6"/>

  <motor name="finger_3_segment_joint_7_actuator" joint="finger_3_segment_joint_7"/>

  <motor name="finger_3_segment_joint_8_actuator" joint="finger_3_segment_joint_8"/>

  <motor name="finger_3_segment_joint_9_actuator" joint="finger_3_segment_joint_9"/>

  </actuator><sensor>
    <force name="force sensor" noise="0" site="force sensor site"/>
  </sensor></mujoco>